{
 "cells": [
  {
   "cell_type": "code",
   "execution_count": 8,
   "metadata": {},
   "outputs": [],
   "source": [
    "import numpy as np\n",
    "import pandas as pd\n",
    "\n",
    "from sklearn.model_selection import GridSearchCV, KFold\n",
    "from sklearn.linear_model import LogisticRegression\n",
    "from sklearn.metrics import accuracy_score, recall_score, roc_auc_score"
   ]
  },
  {
   "cell_type": "code",
   "execution_count": 9,
   "metadata": {},
   "outputs": [],
   "source": [
    "data10 = pd.read_csv(r'C:\\Users\\ddaga\\Desktop\\Assorted\\Projects\\HIGGSBosonCOMP4730\\Dataset\\higgs10k.csv')"
   ]
  },
  {
   "cell_type": "code",
   "execution_count": 10,
   "metadata": {},
   "outputs": [],
   "source": [
    "X = data10.iloc[:, 1:]\n",
    "y = data10.iloc[:, 0]"
   ]
  },
  {
   "cell_type": "code",
   "execution_count": 11,
   "metadata": {},
   "outputs": [],
   "source": [
    "kf = KFold(n_splits=10, shuffle=True, random_state=42)\n",
    "\n",
    "param_grid = {\n",
    "    'penalty': ['l1', 'l2', 'elasticnet', None],\n",
    "    'solver': ['liblinear', 'newton-cg', 'newton-cholesky', 'lbfgs', 'sag', 'saga']  \n",
    "}\n",
    "\n",
    "lr = LogisticRegression(random_state=42)\n",
    "\n",
    "grid_search = GridSearchCV(estimator=lr, param_grid=param_grid, cv=kf, scoring='accuracy')\n",
    "\n",
    "accuracies = []\n",
    "recalls = []\n",
    "auc_scores = []"
   ]
  },
  {
   "cell_type": "code",
   "execution_count": 12,
   "metadata": {},
   "outputs": [
    {
     "name": "stderr",
     "output_type": "stream",
     "text": [
      "c:\\Users\\ddaga\\AppData\\Local\\Programs\\Python\\Python39\\lib\\site-packages\\sklearn\\linear_model\\_sag.py:350: ConvergenceWarning: The max_iter was reached which means the coef_ did not converge\n",
      "  warnings.warn(\n",
      "c:\\Users\\ddaga\\AppData\\Local\\Programs\\Python\\Python39\\lib\\site-packages\\sklearn\\linear_model\\_sag.py:350: ConvergenceWarning: The max_iter was reached which means the coef_ did not converge\n",
      "  warnings.warn(\n",
      "c:\\Users\\ddaga\\AppData\\Local\\Programs\\Python\\Python39\\lib\\site-packages\\sklearn\\linear_model\\_sag.py:350: ConvergenceWarning: The max_iter was reached which means the coef_ did not converge\n",
      "  warnings.warn(\n",
      "c:\\Users\\ddaga\\AppData\\Local\\Programs\\Python\\Python39\\lib\\site-packages\\sklearn\\linear_model\\_sag.py:350: ConvergenceWarning: The max_iter was reached which means the coef_ did not converge\n",
      "  warnings.warn(\n",
      "c:\\Users\\ddaga\\AppData\\Local\\Programs\\Python\\Python39\\lib\\site-packages\\sklearn\\linear_model\\_sag.py:350: ConvergenceWarning: The max_iter was reached which means the coef_ did not converge\n",
      "  warnings.warn(\n",
      "c:\\Users\\ddaga\\AppData\\Local\\Programs\\Python\\Python39\\lib\\site-packages\\sklearn\\linear_model\\_sag.py:350: ConvergenceWarning: The max_iter was reached which means the coef_ did not converge\n",
      "  warnings.warn(\n",
      "c:\\Users\\ddaga\\AppData\\Local\\Programs\\Python\\Python39\\lib\\site-packages\\sklearn\\linear_model\\_sag.py:350: ConvergenceWarning: The max_iter was reached which means the coef_ did not converge\n",
      "  warnings.warn(\n",
      "c:\\Users\\ddaga\\AppData\\Local\\Programs\\Python\\Python39\\lib\\site-packages\\sklearn\\linear_model\\_sag.py:350: ConvergenceWarning: The max_iter was reached which means the coef_ did not converge\n",
      "  warnings.warn(\n",
      "c:\\Users\\ddaga\\AppData\\Local\\Programs\\Python\\Python39\\lib\\site-packages\\sklearn\\linear_model\\_sag.py:350: ConvergenceWarning: The max_iter was reached which means the coef_ did not converge\n",
      "  warnings.warn(\n",
      "c:\\Users\\ddaga\\AppData\\Local\\Programs\\Python\\Python39\\lib\\site-packages\\sklearn\\model_selection\\_validation.py:378: FitFailedWarning: \n",
      "170 fits failed out of a total of 240.\n",
      "The score on these train-test partitions for these parameters will be set to nan.\n",
      "If these failures are not expected, you can try to debug them by setting error_score='raise'.\n",
      "\n",
      "Below are more details about the failures:\n",
      "--------------------------------------------------------------------------------\n",
      "10 fits failed with the following error:\n",
      "Traceback (most recent call last):\n",
      "  File \"c:\\Users\\ddaga\\AppData\\Local\\Programs\\Python\\Python39\\lib\\site-packages\\sklearn\\model_selection\\_validation.py\", line 686, in _fit_and_score\n",
      "    estimator.fit(X_train, y_train, **fit_params)\n",
      "  File \"c:\\Users\\ddaga\\AppData\\Local\\Programs\\Python\\Python39\\lib\\site-packages\\sklearn\\linear_model\\_logistic.py\", line 1091, in fit\n",
      "    solver = _check_solver(self.solver, self.penalty, self.dual)\n",
      "  File \"c:\\Users\\ddaga\\AppData\\Local\\Programs\\Python\\Python39\\lib\\site-packages\\sklearn\\linear_model\\_logistic.py\", line 61, in _check_solver\n",
      "    raise ValueError(\n",
      "ValueError: Solver newton-cg supports only 'l2' or 'none' penalties, got l1 penalty.\n",
      "\n",
      "--------------------------------------------------------------------------------\n",
      "40 fits failed with the following error:\n",
      "Traceback (most recent call last):\n",
      "  File \"c:\\Users\\ddaga\\AppData\\Local\\Programs\\Python\\Python39\\lib\\site-packages\\sklearn\\model_selection\\_validation.py\", line 686, in _fit_and_score\n",
      "    estimator.fit(X_train, y_train, **fit_params)\n",
      "  File \"c:\\Users\\ddaga\\AppData\\Local\\Programs\\Python\\Python39\\lib\\site-packages\\sklearn\\linear_model\\_logistic.py\", line 1091, in fit\n",
      "    solver = _check_solver(self.solver, self.penalty, self.dual)\n",
      "  File \"c:\\Users\\ddaga\\AppData\\Local\\Programs\\Python\\Python39\\lib\\site-packages\\sklearn\\linear_model\\_logistic.py\", line 48, in _check_solver\n",
      "    raise ValueError(\n",
      "ValueError: Logistic Regression supports only solvers in ['liblinear', 'newton-cg', 'lbfgs', 'sag', 'saga'], got newton-cholesky.\n",
      "\n",
      "--------------------------------------------------------------------------------\n",
      "10 fits failed with the following error:\n",
      "Traceback (most recent call last):\n",
      "  File \"c:\\Users\\ddaga\\AppData\\Local\\Programs\\Python\\Python39\\lib\\site-packages\\sklearn\\model_selection\\_validation.py\", line 686, in _fit_and_score\n",
      "    estimator.fit(X_train, y_train, **fit_params)\n",
      "  File \"c:\\Users\\ddaga\\AppData\\Local\\Programs\\Python\\Python39\\lib\\site-packages\\sklearn\\linear_model\\_logistic.py\", line 1091, in fit\n",
      "    solver = _check_solver(self.solver, self.penalty, self.dual)\n",
      "  File \"c:\\Users\\ddaga\\AppData\\Local\\Programs\\Python\\Python39\\lib\\site-packages\\sklearn\\linear_model\\_logistic.py\", line 61, in _check_solver\n",
      "    raise ValueError(\n",
      "ValueError: Solver lbfgs supports only 'l2' or 'none' penalties, got l1 penalty.\n",
      "\n",
      "--------------------------------------------------------------------------------\n",
      "10 fits failed with the following error:\n",
      "Traceback (most recent call last):\n",
      "  File \"c:\\Users\\ddaga\\AppData\\Local\\Programs\\Python\\Python39\\lib\\site-packages\\sklearn\\model_selection\\_validation.py\", line 686, in _fit_and_score\n",
      "    estimator.fit(X_train, y_train, **fit_params)\n",
      "  File \"c:\\Users\\ddaga\\AppData\\Local\\Programs\\Python\\Python39\\lib\\site-packages\\sklearn\\linear_model\\_logistic.py\", line 1091, in fit\n",
      "    solver = _check_solver(self.solver, self.penalty, self.dual)\n",
      "  File \"c:\\Users\\ddaga\\AppData\\Local\\Programs\\Python\\Python39\\lib\\site-packages\\sklearn\\linear_model\\_logistic.py\", line 61, in _check_solver\n",
      "    raise ValueError(\n",
      "ValueError: Solver sag supports only 'l2' or 'none' penalties, got l1 penalty.\n",
      "\n",
      "--------------------------------------------------------------------------------\n",
      "10 fits failed with the following error:\n",
      "Traceback (most recent call last):\n",
      "  File \"c:\\Users\\ddaga\\AppData\\Local\\Programs\\Python\\Python39\\lib\\site-packages\\sklearn\\model_selection\\_validation.py\", line 686, in _fit_and_score\n",
      "    estimator.fit(X_train, y_train, **fit_params)\n",
      "  File \"c:\\Users\\ddaga\\AppData\\Local\\Programs\\Python\\Python39\\lib\\site-packages\\sklearn\\linear_model\\_logistic.py\", line 1091, in fit\n",
      "    solver = _check_solver(self.solver, self.penalty, self.dual)\n",
      "  File \"c:\\Users\\ddaga\\AppData\\Local\\Programs\\Python\\Python39\\lib\\site-packages\\sklearn\\linear_model\\_logistic.py\", line 71, in _check_solver\n",
      "    raise ValueError(\n",
      "ValueError: Only 'saga' solver supports elasticnet penalty, got solver=liblinear.\n",
      "\n",
      "--------------------------------------------------------------------------------\n",
      "10 fits failed with the following error:\n",
      "Traceback (most recent call last):\n",
      "  File \"c:\\Users\\ddaga\\AppData\\Local\\Programs\\Python\\Python39\\lib\\site-packages\\sklearn\\model_selection\\_validation.py\", line 686, in _fit_and_score\n",
      "    estimator.fit(X_train, y_train, **fit_params)\n",
      "  File \"c:\\Users\\ddaga\\AppData\\Local\\Programs\\Python\\Python39\\lib\\site-packages\\sklearn\\linear_model\\_logistic.py\", line 1091, in fit\n",
      "    solver = _check_solver(self.solver, self.penalty, self.dual)\n",
      "  File \"c:\\Users\\ddaga\\AppData\\Local\\Programs\\Python\\Python39\\lib\\site-packages\\sklearn\\linear_model\\_logistic.py\", line 61, in _check_solver\n",
      "    raise ValueError(\n",
      "ValueError: Solver newton-cg supports only 'l2' or 'none' penalties, got elasticnet penalty.\n",
      "\n",
      "--------------------------------------------------------------------------------\n",
      "10 fits failed with the following error:\n",
      "Traceback (most recent call last):\n",
      "  File \"c:\\Users\\ddaga\\AppData\\Local\\Programs\\Python\\Python39\\lib\\site-packages\\sklearn\\model_selection\\_validation.py\", line 686, in _fit_and_score\n",
      "    estimator.fit(X_train, y_train, **fit_params)\n",
      "  File \"c:\\Users\\ddaga\\AppData\\Local\\Programs\\Python\\Python39\\lib\\site-packages\\sklearn\\linear_model\\_logistic.py\", line 1091, in fit\n",
      "    solver = _check_solver(self.solver, self.penalty, self.dual)\n",
      "  File \"c:\\Users\\ddaga\\AppData\\Local\\Programs\\Python\\Python39\\lib\\site-packages\\sklearn\\linear_model\\_logistic.py\", line 61, in _check_solver\n",
      "    raise ValueError(\n",
      "ValueError: Solver lbfgs supports only 'l2' or 'none' penalties, got elasticnet penalty.\n",
      "\n",
      "--------------------------------------------------------------------------------\n",
      "10 fits failed with the following error:\n",
      "Traceback (most recent call last):\n",
      "  File \"c:\\Users\\ddaga\\AppData\\Local\\Programs\\Python\\Python39\\lib\\site-packages\\sklearn\\model_selection\\_validation.py\", line 686, in _fit_and_score\n",
      "    estimator.fit(X_train, y_train, **fit_params)\n",
      "  File \"c:\\Users\\ddaga\\AppData\\Local\\Programs\\Python\\Python39\\lib\\site-packages\\sklearn\\linear_model\\_logistic.py\", line 1091, in fit\n",
      "    solver = _check_solver(self.solver, self.penalty, self.dual)\n",
      "  File \"c:\\Users\\ddaga\\AppData\\Local\\Programs\\Python\\Python39\\lib\\site-packages\\sklearn\\linear_model\\_logistic.py\", line 61, in _check_solver\n",
      "    raise ValueError(\n",
      "ValueError: Solver sag supports only 'l2' or 'none' penalties, got elasticnet penalty.\n",
      "\n",
      "--------------------------------------------------------------------------------\n",
      "10 fits failed with the following error:\n",
      "Traceback (most recent call last):\n",
      "  File \"c:\\Users\\ddaga\\AppData\\Local\\Programs\\Python\\Python39\\lib\\site-packages\\sklearn\\model_selection\\_validation.py\", line 686, in _fit_and_score\n",
      "    estimator.fit(X_train, y_train, **fit_params)\n",
      "  File \"c:\\Users\\ddaga\\AppData\\Local\\Programs\\Python\\Python39\\lib\\site-packages\\sklearn\\linear_model\\_logistic.py\", line 1101, in fit\n",
      "    raise ValueError(\n",
      "ValueError: l1_ratio must be between 0 and 1; got (l1_ratio=None)\n",
      "\n",
      "--------------------------------------------------------------------------------\n",
      "50 fits failed with the following error:\n",
      "Traceback (most recent call last):\n",
      "  File \"c:\\Users\\ddaga\\AppData\\Local\\Programs\\Python\\Python39\\lib\\site-packages\\sklearn\\model_selection\\_validation.py\", line 686, in _fit_and_score\n",
      "    estimator.fit(X_train, y_train, **fit_params)\n",
      "  File \"c:\\Users\\ddaga\\AppData\\Local\\Programs\\Python\\Python39\\lib\\site-packages\\sklearn\\linear_model\\_logistic.py\", line 1091, in fit\n",
      "    solver = _check_solver(self.solver, self.penalty, self.dual)\n",
      "  File \"c:\\Users\\ddaga\\AppData\\Local\\Programs\\Python\\Python39\\lib\\site-packages\\sklearn\\linear_model\\_logistic.py\", line 55, in _check_solver\n",
      "    raise ValueError(\n",
      "ValueError: Logistic Regression supports only penalties in ['l1', 'l2', 'elasticnet', 'none'], got None.\n",
      "\n",
      "  warnings.warn(some_fits_failed_message, FitFailedWarning)\n",
      "c:\\Users\\ddaga\\AppData\\Local\\Programs\\Python\\Python39\\lib\\site-packages\\sklearn\\model_selection\\_search.py:953: UserWarning: One or more of the test scores are non-finite: [0.64255556        nan        nan        nan        nan 0.643\n",
      " 0.64111111 0.64122222        nan 0.64122222 0.64122222 0.64122222\n",
      "        nan        nan        nan        nan        nan        nan\n",
      "        nan        nan        nan        nan        nan        nan]\n",
      "  warnings.warn(\n",
      "c:\\Users\\ddaga\\AppData\\Local\\Programs\\Python\\Python39\\lib\\site-packages\\sklearn\\linear_model\\_sag.py:350: ConvergenceWarning: The max_iter was reached which means the coef_ did not converge\n",
      "  warnings.warn(\n",
      "c:\\Users\\ddaga\\AppData\\Local\\Programs\\Python\\Python39\\lib\\site-packages\\sklearn\\linear_model\\_sag.py:350: ConvergenceWarning: The max_iter was reached which means the coef_ did not converge\n",
      "  warnings.warn(\n",
      "c:\\Users\\ddaga\\AppData\\Local\\Programs\\Python\\Python39\\lib\\site-packages\\sklearn\\linear_model\\_sag.py:350: ConvergenceWarning: The max_iter was reached which means the coef_ did not converge\n",
      "  warnings.warn(\n",
      "c:\\Users\\ddaga\\AppData\\Local\\Programs\\Python\\Python39\\lib\\site-packages\\sklearn\\linear_model\\_sag.py:350: ConvergenceWarning: The max_iter was reached which means the coef_ did not converge\n",
      "  warnings.warn(\n",
      "c:\\Users\\ddaga\\AppData\\Local\\Programs\\Python\\Python39\\lib\\site-packages\\sklearn\\linear_model\\_sag.py:350: ConvergenceWarning: The max_iter was reached which means the coef_ did not converge\n",
      "  warnings.warn(\n",
      "c:\\Users\\ddaga\\AppData\\Local\\Programs\\Python\\Python39\\lib\\site-packages\\sklearn\\linear_model\\_sag.py:350: ConvergenceWarning: The max_iter was reached which means the coef_ did not converge\n",
      "  warnings.warn(\n",
      "c:\\Users\\ddaga\\AppData\\Local\\Programs\\Python\\Python39\\lib\\site-packages\\sklearn\\linear_model\\_sag.py:350: ConvergenceWarning: The max_iter was reached which means the coef_ did not converge\n",
      "  warnings.warn(\n",
      "c:\\Users\\ddaga\\AppData\\Local\\Programs\\Python\\Python39\\lib\\site-packages\\sklearn\\linear_model\\_sag.py:350: ConvergenceWarning: The max_iter was reached which means the coef_ did not converge\n",
      "  warnings.warn(\n",
      "c:\\Users\\ddaga\\AppData\\Local\\Programs\\Python\\Python39\\lib\\site-packages\\sklearn\\linear_model\\_sag.py:350: ConvergenceWarning: The max_iter was reached which means the coef_ did not converge\n",
      "  warnings.warn(\n",
      "c:\\Users\\ddaga\\AppData\\Local\\Programs\\Python\\Python39\\lib\\site-packages\\sklearn\\model_selection\\_validation.py:378: FitFailedWarning: \n",
      "170 fits failed out of a total of 240.\n",
      "The score on these train-test partitions for these parameters will be set to nan.\n",
      "If these failures are not expected, you can try to debug them by setting error_score='raise'.\n",
      "\n",
      "Below are more details about the failures:\n",
      "--------------------------------------------------------------------------------\n",
      "10 fits failed with the following error:\n",
      "Traceback (most recent call last):\n",
      "  File \"c:\\Users\\ddaga\\AppData\\Local\\Programs\\Python\\Python39\\lib\\site-packages\\sklearn\\model_selection\\_validation.py\", line 686, in _fit_and_score\n",
      "    estimator.fit(X_train, y_train, **fit_params)\n",
      "  File \"c:\\Users\\ddaga\\AppData\\Local\\Programs\\Python\\Python39\\lib\\site-packages\\sklearn\\linear_model\\_logistic.py\", line 1091, in fit\n",
      "    solver = _check_solver(self.solver, self.penalty, self.dual)\n",
      "  File \"c:\\Users\\ddaga\\AppData\\Local\\Programs\\Python\\Python39\\lib\\site-packages\\sklearn\\linear_model\\_logistic.py\", line 61, in _check_solver\n",
      "    raise ValueError(\n",
      "ValueError: Solver newton-cg supports only 'l2' or 'none' penalties, got l1 penalty.\n",
      "\n",
      "--------------------------------------------------------------------------------\n",
      "40 fits failed with the following error:\n",
      "Traceback (most recent call last):\n",
      "  File \"c:\\Users\\ddaga\\AppData\\Local\\Programs\\Python\\Python39\\lib\\site-packages\\sklearn\\model_selection\\_validation.py\", line 686, in _fit_and_score\n",
      "    estimator.fit(X_train, y_train, **fit_params)\n",
      "  File \"c:\\Users\\ddaga\\AppData\\Local\\Programs\\Python\\Python39\\lib\\site-packages\\sklearn\\linear_model\\_logistic.py\", line 1091, in fit\n",
      "    solver = _check_solver(self.solver, self.penalty, self.dual)\n",
      "  File \"c:\\Users\\ddaga\\AppData\\Local\\Programs\\Python\\Python39\\lib\\site-packages\\sklearn\\linear_model\\_logistic.py\", line 48, in _check_solver\n",
      "    raise ValueError(\n",
      "ValueError: Logistic Regression supports only solvers in ['liblinear', 'newton-cg', 'lbfgs', 'sag', 'saga'], got newton-cholesky.\n",
      "\n",
      "--------------------------------------------------------------------------------\n",
      "10 fits failed with the following error:\n",
      "Traceback (most recent call last):\n",
      "  File \"c:\\Users\\ddaga\\AppData\\Local\\Programs\\Python\\Python39\\lib\\site-packages\\sklearn\\model_selection\\_validation.py\", line 686, in _fit_and_score\n",
      "    estimator.fit(X_train, y_train, **fit_params)\n",
      "  File \"c:\\Users\\ddaga\\AppData\\Local\\Programs\\Python\\Python39\\lib\\site-packages\\sklearn\\linear_model\\_logistic.py\", line 1091, in fit\n",
      "    solver = _check_solver(self.solver, self.penalty, self.dual)\n",
      "  File \"c:\\Users\\ddaga\\AppData\\Local\\Programs\\Python\\Python39\\lib\\site-packages\\sklearn\\linear_model\\_logistic.py\", line 61, in _check_solver\n",
      "    raise ValueError(\n",
      "ValueError: Solver lbfgs supports only 'l2' or 'none' penalties, got l1 penalty.\n",
      "\n",
      "--------------------------------------------------------------------------------\n",
      "10 fits failed with the following error:\n",
      "Traceback (most recent call last):\n",
      "  File \"c:\\Users\\ddaga\\AppData\\Local\\Programs\\Python\\Python39\\lib\\site-packages\\sklearn\\model_selection\\_validation.py\", line 686, in _fit_and_score\n",
      "    estimator.fit(X_train, y_train, **fit_params)\n",
      "  File \"c:\\Users\\ddaga\\AppData\\Local\\Programs\\Python\\Python39\\lib\\site-packages\\sklearn\\linear_model\\_logistic.py\", line 1091, in fit\n",
      "    solver = _check_solver(self.solver, self.penalty, self.dual)\n",
      "  File \"c:\\Users\\ddaga\\AppData\\Local\\Programs\\Python\\Python39\\lib\\site-packages\\sklearn\\linear_model\\_logistic.py\", line 61, in _check_solver\n",
      "    raise ValueError(\n",
      "ValueError: Solver sag supports only 'l2' or 'none' penalties, got l1 penalty.\n",
      "\n",
      "--------------------------------------------------------------------------------\n",
      "10 fits failed with the following error:\n",
      "Traceback (most recent call last):\n",
      "  File \"c:\\Users\\ddaga\\AppData\\Local\\Programs\\Python\\Python39\\lib\\site-packages\\sklearn\\model_selection\\_validation.py\", line 686, in _fit_and_score\n",
      "    estimator.fit(X_train, y_train, **fit_params)\n",
      "  File \"c:\\Users\\ddaga\\AppData\\Local\\Programs\\Python\\Python39\\lib\\site-packages\\sklearn\\linear_model\\_logistic.py\", line 1091, in fit\n",
      "    solver = _check_solver(self.solver, self.penalty, self.dual)\n",
      "  File \"c:\\Users\\ddaga\\AppData\\Local\\Programs\\Python\\Python39\\lib\\site-packages\\sklearn\\linear_model\\_logistic.py\", line 71, in _check_solver\n",
      "    raise ValueError(\n",
      "ValueError: Only 'saga' solver supports elasticnet penalty, got solver=liblinear.\n",
      "\n",
      "--------------------------------------------------------------------------------\n",
      "10 fits failed with the following error:\n",
      "Traceback (most recent call last):\n",
      "  File \"c:\\Users\\ddaga\\AppData\\Local\\Programs\\Python\\Python39\\lib\\site-packages\\sklearn\\model_selection\\_validation.py\", line 686, in _fit_and_score\n",
      "    estimator.fit(X_train, y_train, **fit_params)\n",
      "  File \"c:\\Users\\ddaga\\AppData\\Local\\Programs\\Python\\Python39\\lib\\site-packages\\sklearn\\linear_model\\_logistic.py\", line 1091, in fit\n",
      "    solver = _check_solver(self.solver, self.penalty, self.dual)\n",
      "  File \"c:\\Users\\ddaga\\AppData\\Local\\Programs\\Python\\Python39\\lib\\site-packages\\sklearn\\linear_model\\_logistic.py\", line 61, in _check_solver\n",
      "    raise ValueError(\n",
      "ValueError: Solver newton-cg supports only 'l2' or 'none' penalties, got elasticnet penalty.\n",
      "\n",
      "--------------------------------------------------------------------------------\n",
      "10 fits failed with the following error:\n",
      "Traceback (most recent call last):\n",
      "  File \"c:\\Users\\ddaga\\AppData\\Local\\Programs\\Python\\Python39\\lib\\site-packages\\sklearn\\model_selection\\_validation.py\", line 686, in _fit_and_score\n",
      "    estimator.fit(X_train, y_train, **fit_params)\n",
      "  File \"c:\\Users\\ddaga\\AppData\\Local\\Programs\\Python\\Python39\\lib\\site-packages\\sklearn\\linear_model\\_logistic.py\", line 1091, in fit\n",
      "    solver = _check_solver(self.solver, self.penalty, self.dual)\n",
      "  File \"c:\\Users\\ddaga\\AppData\\Local\\Programs\\Python\\Python39\\lib\\site-packages\\sklearn\\linear_model\\_logistic.py\", line 61, in _check_solver\n",
      "    raise ValueError(\n",
      "ValueError: Solver lbfgs supports only 'l2' or 'none' penalties, got elasticnet penalty.\n",
      "\n",
      "--------------------------------------------------------------------------------\n",
      "10 fits failed with the following error:\n",
      "Traceback (most recent call last):\n",
      "  File \"c:\\Users\\ddaga\\AppData\\Local\\Programs\\Python\\Python39\\lib\\site-packages\\sklearn\\model_selection\\_validation.py\", line 686, in _fit_and_score\n",
      "    estimator.fit(X_train, y_train, **fit_params)\n",
      "  File \"c:\\Users\\ddaga\\AppData\\Local\\Programs\\Python\\Python39\\lib\\site-packages\\sklearn\\linear_model\\_logistic.py\", line 1091, in fit\n",
      "    solver = _check_solver(self.solver, self.penalty, self.dual)\n",
      "  File \"c:\\Users\\ddaga\\AppData\\Local\\Programs\\Python\\Python39\\lib\\site-packages\\sklearn\\linear_model\\_logistic.py\", line 61, in _check_solver\n",
      "    raise ValueError(\n",
      "ValueError: Solver sag supports only 'l2' or 'none' penalties, got elasticnet penalty.\n",
      "\n",
      "--------------------------------------------------------------------------------\n",
      "10 fits failed with the following error:\n",
      "Traceback (most recent call last):\n",
      "  File \"c:\\Users\\ddaga\\AppData\\Local\\Programs\\Python\\Python39\\lib\\site-packages\\sklearn\\model_selection\\_validation.py\", line 686, in _fit_and_score\n",
      "    estimator.fit(X_train, y_train, **fit_params)\n",
      "  File \"c:\\Users\\ddaga\\AppData\\Local\\Programs\\Python\\Python39\\lib\\site-packages\\sklearn\\linear_model\\_logistic.py\", line 1101, in fit\n",
      "    raise ValueError(\n",
      "ValueError: l1_ratio must be between 0 and 1; got (l1_ratio=None)\n",
      "\n",
      "--------------------------------------------------------------------------------\n",
      "50 fits failed with the following error:\n",
      "Traceback (most recent call last):\n",
      "  File \"c:\\Users\\ddaga\\AppData\\Local\\Programs\\Python\\Python39\\lib\\site-packages\\sklearn\\model_selection\\_validation.py\", line 686, in _fit_and_score\n",
      "    estimator.fit(X_train, y_train, **fit_params)\n",
      "  File \"c:\\Users\\ddaga\\AppData\\Local\\Programs\\Python\\Python39\\lib\\site-packages\\sklearn\\linear_model\\_logistic.py\", line 1091, in fit\n",
      "    solver = _check_solver(self.solver, self.penalty, self.dual)\n",
      "  File \"c:\\Users\\ddaga\\AppData\\Local\\Programs\\Python\\Python39\\lib\\site-packages\\sklearn\\linear_model\\_logistic.py\", line 55, in _check_solver\n",
      "    raise ValueError(\n",
      "ValueError: Logistic Regression supports only penalties in ['l1', 'l2', 'elasticnet', 'none'], got None.\n",
      "\n",
      "  warnings.warn(some_fits_failed_message, FitFailedWarning)\n",
      "c:\\Users\\ddaga\\AppData\\Local\\Programs\\Python\\Python39\\lib\\site-packages\\sklearn\\model_selection\\_search.py:953: UserWarning: One or more of the test scores are non-finite: [0.63988889        nan        nan        nan        nan 0.64044444\n",
      " 0.63944444 0.63966667        nan 0.63966667 0.63966667 0.63966667\n",
      "        nan        nan        nan        nan        nan        nan\n",
      "        nan        nan        nan        nan        nan        nan]\n",
      "  warnings.warn(\n",
      "c:\\Users\\ddaga\\AppData\\Local\\Programs\\Python\\Python39\\lib\\site-packages\\sklearn\\linear_model\\_sag.py:350: ConvergenceWarning: The max_iter was reached which means the coef_ did not converge\n",
      "  warnings.warn(\n",
      "c:\\Users\\ddaga\\AppData\\Local\\Programs\\Python\\Python39\\lib\\site-packages\\sklearn\\linear_model\\_sag.py:350: ConvergenceWarning: The max_iter was reached which means the coef_ did not converge\n",
      "  warnings.warn(\n",
      "c:\\Users\\ddaga\\AppData\\Local\\Programs\\Python\\Python39\\lib\\site-packages\\sklearn\\linear_model\\_sag.py:350: ConvergenceWarning: The max_iter was reached which means the coef_ did not converge\n",
      "  warnings.warn(\n",
      "c:\\Users\\ddaga\\AppData\\Local\\Programs\\Python\\Python39\\lib\\site-packages\\sklearn\\linear_model\\_sag.py:350: ConvergenceWarning: The max_iter was reached which means the coef_ did not converge\n",
      "  warnings.warn(\n",
      "c:\\Users\\ddaga\\AppData\\Local\\Programs\\Python\\Python39\\lib\\site-packages\\sklearn\\linear_model\\_sag.py:350: ConvergenceWarning: The max_iter was reached which means the coef_ did not converge\n",
      "  warnings.warn(\n",
      "c:\\Users\\ddaga\\AppData\\Local\\Programs\\Python\\Python39\\lib\\site-packages\\sklearn\\linear_model\\_sag.py:350: ConvergenceWarning: The max_iter was reached which means the coef_ did not converge\n",
      "  warnings.warn(\n",
      "c:\\Users\\ddaga\\AppData\\Local\\Programs\\Python\\Python39\\lib\\site-packages\\sklearn\\linear_model\\_sag.py:350: ConvergenceWarning: The max_iter was reached which means the coef_ did not converge\n",
      "  warnings.warn(\n",
      "c:\\Users\\ddaga\\AppData\\Local\\Programs\\Python\\Python39\\lib\\site-packages\\sklearn\\linear_model\\_sag.py:350: ConvergenceWarning: The max_iter was reached which means the coef_ did not converge\n",
      "  warnings.warn(\n",
      "c:\\Users\\ddaga\\AppData\\Local\\Programs\\Python\\Python39\\lib\\site-packages\\sklearn\\linear_model\\_sag.py:350: ConvergenceWarning: The max_iter was reached which means the coef_ did not converge\n",
      "  warnings.warn(\n",
      "c:\\Users\\ddaga\\AppData\\Local\\Programs\\Python\\Python39\\lib\\site-packages\\sklearn\\model_selection\\_validation.py:378: FitFailedWarning: \n",
      "170 fits failed out of a total of 240.\n",
      "The score on these train-test partitions for these parameters will be set to nan.\n",
      "If these failures are not expected, you can try to debug them by setting error_score='raise'.\n",
      "\n",
      "Below are more details about the failures:\n",
      "--------------------------------------------------------------------------------\n",
      "10 fits failed with the following error:\n",
      "Traceback (most recent call last):\n",
      "  File \"c:\\Users\\ddaga\\AppData\\Local\\Programs\\Python\\Python39\\lib\\site-packages\\sklearn\\model_selection\\_validation.py\", line 686, in _fit_and_score\n",
      "    estimator.fit(X_train, y_train, **fit_params)\n",
      "  File \"c:\\Users\\ddaga\\AppData\\Local\\Programs\\Python\\Python39\\lib\\site-packages\\sklearn\\linear_model\\_logistic.py\", line 1091, in fit\n",
      "    solver = _check_solver(self.solver, self.penalty, self.dual)\n",
      "  File \"c:\\Users\\ddaga\\AppData\\Local\\Programs\\Python\\Python39\\lib\\site-packages\\sklearn\\linear_model\\_logistic.py\", line 61, in _check_solver\n",
      "    raise ValueError(\n",
      "ValueError: Solver newton-cg supports only 'l2' or 'none' penalties, got l1 penalty.\n",
      "\n",
      "--------------------------------------------------------------------------------\n",
      "40 fits failed with the following error:\n",
      "Traceback (most recent call last):\n",
      "  File \"c:\\Users\\ddaga\\AppData\\Local\\Programs\\Python\\Python39\\lib\\site-packages\\sklearn\\model_selection\\_validation.py\", line 686, in _fit_and_score\n",
      "    estimator.fit(X_train, y_train, **fit_params)\n",
      "  File \"c:\\Users\\ddaga\\AppData\\Local\\Programs\\Python\\Python39\\lib\\site-packages\\sklearn\\linear_model\\_logistic.py\", line 1091, in fit\n",
      "    solver = _check_solver(self.solver, self.penalty, self.dual)\n",
      "  File \"c:\\Users\\ddaga\\AppData\\Local\\Programs\\Python\\Python39\\lib\\site-packages\\sklearn\\linear_model\\_logistic.py\", line 48, in _check_solver\n",
      "    raise ValueError(\n",
      "ValueError: Logistic Regression supports only solvers in ['liblinear', 'newton-cg', 'lbfgs', 'sag', 'saga'], got newton-cholesky.\n",
      "\n",
      "--------------------------------------------------------------------------------\n",
      "10 fits failed with the following error:\n",
      "Traceback (most recent call last):\n",
      "  File \"c:\\Users\\ddaga\\AppData\\Local\\Programs\\Python\\Python39\\lib\\site-packages\\sklearn\\model_selection\\_validation.py\", line 686, in _fit_and_score\n",
      "    estimator.fit(X_train, y_train, **fit_params)\n",
      "  File \"c:\\Users\\ddaga\\AppData\\Local\\Programs\\Python\\Python39\\lib\\site-packages\\sklearn\\linear_model\\_logistic.py\", line 1091, in fit\n",
      "    solver = _check_solver(self.solver, self.penalty, self.dual)\n",
      "  File \"c:\\Users\\ddaga\\AppData\\Local\\Programs\\Python\\Python39\\lib\\site-packages\\sklearn\\linear_model\\_logistic.py\", line 61, in _check_solver\n",
      "    raise ValueError(\n",
      "ValueError: Solver lbfgs supports only 'l2' or 'none' penalties, got l1 penalty.\n",
      "\n",
      "--------------------------------------------------------------------------------\n",
      "10 fits failed with the following error:\n",
      "Traceback (most recent call last):\n",
      "  File \"c:\\Users\\ddaga\\AppData\\Local\\Programs\\Python\\Python39\\lib\\site-packages\\sklearn\\model_selection\\_validation.py\", line 686, in _fit_and_score\n",
      "    estimator.fit(X_train, y_train, **fit_params)\n",
      "  File \"c:\\Users\\ddaga\\AppData\\Local\\Programs\\Python\\Python39\\lib\\site-packages\\sklearn\\linear_model\\_logistic.py\", line 1091, in fit\n",
      "    solver = _check_solver(self.solver, self.penalty, self.dual)\n",
      "  File \"c:\\Users\\ddaga\\AppData\\Local\\Programs\\Python\\Python39\\lib\\site-packages\\sklearn\\linear_model\\_logistic.py\", line 61, in _check_solver\n",
      "    raise ValueError(\n",
      "ValueError: Solver sag supports only 'l2' or 'none' penalties, got l1 penalty.\n",
      "\n",
      "--------------------------------------------------------------------------------\n",
      "10 fits failed with the following error:\n",
      "Traceback (most recent call last):\n",
      "  File \"c:\\Users\\ddaga\\AppData\\Local\\Programs\\Python\\Python39\\lib\\site-packages\\sklearn\\model_selection\\_validation.py\", line 686, in _fit_and_score\n",
      "    estimator.fit(X_train, y_train, **fit_params)\n",
      "  File \"c:\\Users\\ddaga\\AppData\\Local\\Programs\\Python\\Python39\\lib\\site-packages\\sklearn\\linear_model\\_logistic.py\", line 1091, in fit\n",
      "    solver = _check_solver(self.solver, self.penalty, self.dual)\n",
      "  File \"c:\\Users\\ddaga\\AppData\\Local\\Programs\\Python\\Python39\\lib\\site-packages\\sklearn\\linear_model\\_logistic.py\", line 71, in _check_solver\n",
      "    raise ValueError(\n",
      "ValueError: Only 'saga' solver supports elasticnet penalty, got solver=liblinear.\n",
      "\n",
      "--------------------------------------------------------------------------------\n",
      "10 fits failed with the following error:\n",
      "Traceback (most recent call last):\n",
      "  File \"c:\\Users\\ddaga\\AppData\\Local\\Programs\\Python\\Python39\\lib\\site-packages\\sklearn\\model_selection\\_validation.py\", line 686, in _fit_and_score\n",
      "    estimator.fit(X_train, y_train, **fit_params)\n",
      "  File \"c:\\Users\\ddaga\\AppData\\Local\\Programs\\Python\\Python39\\lib\\site-packages\\sklearn\\linear_model\\_logistic.py\", line 1091, in fit\n",
      "    solver = _check_solver(self.solver, self.penalty, self.dual)\n",
      "  File \"c:\\Users\\ddaga\\AppData\\Local\\Programs\\Python\\Python39\\lib\\site-packages\\sklearn\\linear_model\\_logistic.py\", line 61, in _check_solver\n",
      "    raise ValueError(\n",
      "ValueError: Solver newton-cg supports only 'l2' or 'none' penalties, got elasticnet penalty.\n",
      "\n",
      "--------------------------------------------------------------------------------\n",
      "10 fits failed with the following error:\n",
      "Traceback (most recent call last):\n",
      "  File \"c:\\Users\\ddaga\\AppData\\Local\\Programs\\Python\\Python39\\lib\\site-packages\\sklearn\\model_selection\\_validation.py\", line 686, in _fit_and_score\n",
      "    estimator.fit(X_train, y_train, **fit_params)\n",
      "  File \"c:\\Users\\ddaga\\AppData\\Local\\Programs\\Python\\Python39\\lib\\site-packages\\sklearn\\linear_model\\_logistic.py\", line 1091, in fit\n",
      "    solver = _check_solver(self.solver, self.penalty, self.dual)\n",
      "  File \"c:\\Users\\ddaga\\AppData\\Local\\Programs\\Python\\Python39\\lib\\site-packages\\sklearn\\linear_model\\_logistic.py\", line 61, in _check_solver\n",
      "    raise ValueError(\n",
      "ValueError: Solver lbfgs supports only 'l2' or 'none' penalties, got elasticnet penalty.\n",
      "\n",
      "--------------------------------------------------------------------------------\n",
      "10 fits failed with the following error:\n",
      "Traceback (most recent call last):\n",
      "  File \"c:\\Users\\ddaga\\AppData\\Local\\Programs\\Python\\Python39\\lib\\site-packages\\sklearn\\model_selection\\_validation.py\", line 686, in _fit_and_score\n",
      "    estimator.fit(X_train, y_train, **fit_params)\n",
      "  File \"c:\\Users\\ddaga\\AppData\\Local\\Programs\\Python\\Python39\\lib\\site-packages\\sklearn\\linear_model\\_logistic.py\", line 1091, in fit\n",
      "    solver = _check_solver(self.solver, self.penalty, self.dual)\n",
      "  File \"c:\\Users\\ddaga\\AppData\\Local\\Programs\\Python\\Python39\\lib\\site-packages\\sklearn\\linear_model\\_logistic.py\", line 61, in _check_solver\n",
      "    raise ValueError(\n",
      "ValueError: Solver sag supports only 'l2' or 'none' penalties, got elasticnet penalty.\n",
      "\n",
      "--------------------------------------------------------------------------------\n",
      "10 fits failed with the following error:\n",
      "Traceback (most recent call last):\n",
      "  File \"c:\\Users\\ddaga\\AppData\\Local\\Programs\\Python\\Python39\\lib\\site-packages\\sklearn\\model_selection\\_validation.py\", line 686, in _fit_and_score\n",
      "    estimator.fit(X_train, y_train, **fit_params)\n",
      "  File \"c:\\Users\\ddaga\\AppData\\Local\\Programs\\Python\\Python39\\lib\\site-packages\\sklearn\\linear_model\\_logistic.py\", line 1101, in fit\n",
      "    raise ValueError(\n",
      "ValueError: l1_ratio must be between 0 and 1; got (l1_ratio=None)\n",
      "\n",
      "--------------------------------------------------------------------------------\n",
      "50 fits failed with the following error:\n",
      "Traceback (most recent call last):\n",
      "  File \"c:\\Users\\ddaga\\AppData\\Local\\Programs\\Python\\Python39\\lib\\site-packages\\sklearn\\model_selection\\_validation.py\", line 686, in _fit_and_score\n",
      "    estimator.fit(X_train, y_train, **fit_params)\n",
      "  File \"c:\\Users\\ddaga\\AppData\\Local\\Programs\\Python\\Python39\\lib\\site-packages\\sklearn\\linear_model\\_logistic.py\", line 1091, in fit\n",
      "    solver = _check_solver(self.solver, self.penalty, self.dual)\n",
      "  File \"c:\\Users\\ddaga\\AppData\\Local\\Programs\\Python\\Python39\\lib\\site-packages\\sklearn\\linear_model\\_logistic.py\", line 55, in _check_solver\n",
      "    raise ValueError(\n",
      "ValueError: Logistic Regression supports only penalties in ['l1', 'l2', 'elasticnet', 'none'], got None.\n",
      "\n",
      "  warnings.warn(some_fits_failed_message, FitFailedWarning)\n",
      "c:\\Users\\ddaga\\AppData\\Local\\Programs\\Python\\Python39\\lib\\site-packages\\sklearn\\model_selection\\_search.py:953: UserWarning: One or more of the test scores are non-finite: [0.64055556        nan        nan        nan        nan 0.64011111\n",
      " 0.64033333 0.64              nan 0.64011111 0.64011111 0.64011111\n",
      "        nan        nan        nan        nan        nan        nan\n",
      "        nan        nan        nan        nan        nan        nan]\n",
      "  warnings.warn(\n",
      "c:\\Users\\ddaga\\AppData\\Local\\Programs\\Python\\Python39\\lib\\site-packages\\sklearn\\linear_model\\_sag.py:350: ConvergenceWarning: The max_iter was reached which means the coef_ did not converge\n",
      "  warnings.warn(\n",
      "c:\\Users\\ddaga\\AppData\\Local\\Programs\\Python\\Python39\\lib\\site-packages\\sklearn\\linear_model\\_sag.py:350: ConvergenceWarning: The max_iter was reached which means the coef_ did not converge\n",
      "  warnings.warn(\n",
      "c:\\Users\\ddaga\\AppData\\Local\\Programs\\Python\\Python39\\lib\\site-packages\\sklearn\\linear_model\\_sag.py:350: ConvergenceWarning: The max_iter was reached which means the coef_ did not converge\n",
      "  warnings.warn(\n",
      "c:\\Users\\ddaga\\AppData\\Local\\Programs\\Python\\Python39\\lib\\site-packages\\sklearn\\linear_model\\_sag.py:350: ConvergenceWarning: The max_iter was reached which means the coef_ did not converge\n",
      "  warnings.warn(\n",
      "c:\\Users\\ddaga\\AppData\\Local\\Programs\\Python\\Python39\\lib\\site-packages\\sklearn\\linear_model\\_sag.py:350: ConvergenceWarning: The max_iter was reached which means the coef_ did not converge\n",
      "  warnings.warn(\n",
      "c:\\Users\\ddaga\\AppData\\Local\\Programs\\Python\\Python39\\lib\\site-packages\\sklearn\\linear_model\\_sag.py:350: ConvergenceWarning: The max_iter was reached which means the coef_ did not converge\n",
      "  warnings.warn(\n",
      "c:\\Users\\ddaga\\AppData\\Local\\Programs\\Python\\Python39\\lib\\site-packages\\sklearn\\linear_model\\_sag.py:350: ConvergenceWarning: The max_iter was reached which means the coef_ did not converge\n",
      "  warnings.warn(\n",
      "c:\\Users\\ddaga\\AppData\\Local\\Programs\\Python\\Python39\\lib\\site-packages\\sklearn\\linear_model\\_sag.py:350: ConvergenceWarning: The max_iter was reached which means the coef_ did not converge\n",
      "  warnings.warn(\n",
      "c:\\Users\\ddaga\\AppData\\Local\\Programs\\Python\\Python39\\lib\\site-packages\\sklearn\\linear_model\\_sag.py:350: ConvergenceWarning: The max_iter was reached which means the coef_ did not converge\n",
      "  warnings.warn(\n",
      "c:\\Users\\ddaga\\AppData\\Local\\Programs\\Python\\Python39\\lib\\site-packages\\sklearn\\model_selection\\_validation.py:378: FitFailedWarning: \n",
      "170 fits failed out of a total of 240.\n",
      "The score on these train-test partitions for these parameters will be set to nan.\n",
      "If these failures are not expected, you can try to debug them by setting error_score='raise'.\n",
      "\n",
      "Below are more details about the failures:\n",
      "--------------------------------------------------------------------------------\n",
      "10 fits failed with the following error:\n",
      "Traceback (most recent call last):\n",
      "  File \"c:\\Users\\ddaga\\AppData\\Local\\Programs\\Python\\Python39\\lib\\site-packages\\sklearn\\model_selection\\_validation.py\", line 686, in _fit_and_score\n",
      "    estimator.fit(X_train, y_train, **fit_params)\n",
      "  File \"c:\\Users\\ddaga\\AppData\\Local\\Programs\\Python\\Python39\\lib\\site-packages\\sklearn\\linear_model\\_logistic.py\", line 1091, in fit\n",
      "    solver = _check_solver(self.solver, self.penalty, self.dual)\n",
      "  File \"c:\\Users\\ddaga\\AppData\\Local\\Programs\\Python\\Python39\\lib\\site-packages\\sklearn\\linear_model\\_logistic.py\", line 61, in _check_solver\n",
      "    raise ValueError(\n",
      "ValueError: Solver newton-cg supports only 'l2' or 'none' penalties, got l1 penalty.\n",
      "\n",
      "--------------------------------------------------------------------------------\n",
      "40 fits failed with the following error:\n",
      "Traceback (most recent call last):\n",
      "  File \"c:\\Users\\ddaga\\AppData\\Local\\Programs\\Python\\Python39\\lib\\site-packages\\sklearn\\model_selection\\_validation.py\", line 686, in _fit_and_score\n",
      "    estimator.fit(X_train, y_train, **fit_params)\n",
      "  File \"c:\\Users\\ddaga\\AppData\\Local\\Programs\\Python\\Python39\\lib\\site-packages\\sklearn\\linear_model\\_logistic.py\", line 1091, in fit\n",
      "    solver = _check_solver(self.solver, self.penalty, self.dual)\n",
      "  File \"c:\\Users\\ddaga\\AppData\\Local\\Programs\\Python\\Python39\\lib\\site-packages\\sklearn\\linear_model\\_logistic.py\", line 48, in _check_solver\n",
      "    raise ValueError(\n",
      "ValueError: Logistic Regression supports only solvers in ['liblinear', 'newton-cg', 'lbfgs', 'sag', 'saga'], got newton-cholesky.\n",
      "\n",
      "--------------------------------------------------------------------------------\n",
      "10 fits failed with the following error:\n",
      "Traceback (most recent call last):\n",
      "  File \"c:\\Users\\ddaga\\AppData\\Local\\Programs\\Python\\Python39\\lib\\site-packages\\sklearn\\model_selection\\_validation.py\", line 686, in _fit_and_score\n",
      "    estimator.fit(X_train, y_train, **fit_params)\n",
      "  File \"c:\\Users\\ddaga\\AppData\\Local\\Programs\\Python\\Python39\\lib\\site-packages\\sklearn\\linear_model\\_logistic.py\", line 1091, in fit\n",
      "    solver = _check_solver(self.solver, self.penalty, self.dual)\n",
      "  File \"c:\\Users\\ddaga\\AppData\\Local\\Programs\\Python\\Python39\\lib\\site-packages\\sklearn\\linear_model\\_logistic.py\", line 61, in _check_solver\n",
      "    raise ValueError(\n",
      "ValueError: Solver lbfgs supports only 'l2' or 'none' penalties, got l1 penalty.\n",
      "\n",
      "--------------------------------------------------------------------------------\n",
      "10 fits failed with the following error:\n",
      "Traceback (most recent call last):\n",
      "  File \"c:\\Users\\ddaga\\AppData\\Local\\Programs\\Python\\Python39\\lib\\site-packages\\sklearn\\model_selection\\_validation.py\", line 686, in _fit_and_score\n",
      "    estimator.fit(X_train, y_train, **fit_params)\n",
      "  File \"c:\\Users\\ddaga\\AppData\\Local\\Programs\\Python\\Python39\\lib\\site-packages\\sklearn\\linear_model\\_logistic.py\", line 1091, in fit\n",
      "    solver = _check_solver(self.solver, self.penalty, self.dual)\n",
      "  File \"c:\\Users\\ddaga\\AppData\\Local\\Programs\\Python\\Python39\\lib\\site-packages\\sklearn\\linear_model\\_logistic.py\", line 61, in _check_solver\n",
      "    raise ValueError(\n",
      "ValueError: Solver sag supports only 'l2' or 'none' penalties, got l1 penalty.\n",
      "\n",
      "--------------------------------------------------------------------------------\n",
      "10 fits failed with the following error:\n",
      "Traceback (most recent call last):\n",
      "  File \"c:\\Users\\ddaga\\AppData\\Local\\Programs\\Python\\Python39\\lib\\site-packages\\sklearn\\model_selection\\_validation.py\", line 686, in _fit_and_score\n",
      "    estimator.fit(X_train, y_train, **fit_params)\n",
      "  File \"c:\\Users\\ddaga\\AppData\\Local\\Programs\\Python\\Python39\\lib\\site-packages\\sklearn\\linear_model\\_logistic.py\", line 1091, in fit\n",
      "    solver = _check_solver(self.solver, self.penalty, self.dual)\n",
      "  File \"c:\\Users\\ddaga\\AppData\\Local\\Programs\\Python\\Python39\\lib\\site-packages\\sklearn\\linear_model\\_logistic.py\", line 71, in _check_solver\n",
      "    raise ValueError(\n",
      "ValueError: Only 'saga' solver supports elasticnet penalty, got solver=liblinear.\n",
      "\n",
      "--------------------------------------------------------------------------------\n",
      "10 fits failed with the following error:\n",
      "Traceback (most recent call last):\n",
      "  File \"c:\\Users\\ddaga\\AppData\\Local\\Programs\\Python\\Python39\\lib\\site-packages\\sklearn\\model_selection\\_validation.py\", line 686, in _fit_and_score\n",
      "    estimator.fit(X_train, y_train, **fit_params)\n",
      "  File \"c:\\Users\\ddaga\\AppData\\Local\\Programs\\Python\\Python39\\lib\\site-packages\\sklearn\\linear_model\\_logistic.py\", line 1091, in fit\n",
      "    solver = _check_solver(self.solver, self.penalty, self.dual)\n",
      "  File \"c:\\Users\\ddaga\\AppData\\Local\\Programs\\Python\\Python39\\lib\\site-packages\\sklearn\\linear_model\\_logistic.py\", line 61, in _check_solver\n",
      "    raise ValueError(\n",
      "ValueError: Solver newton-cg supports only 'l2' or 'none' penalties, got elasticnet penalty.\n",
      "\n",
      "--------------------------------------------------------------------------------\n",
      "10 fits failed with the following error:\n",
      "Traceback (most recent call last):\n",
      "  File \"c:\\Users\\ddaga\\AppData\\Local\\Programs\\Python\\Python39\\lib\\site-packages\\sklearn\\model_selection\\_validation.py\", line 686, in _fit_and_score\n",
      "    estimator.fit(X_train, y_train, **fit_params)\n",
      "  File \"c:\\Users\\ddaga\\AppData\\Local\\Programs\\Python\\Python39\\lib\\site-packages\\sklearn\\linear_model\\_logistic.py\", line 1091, in fit\n",
      "    solver = _check_solver(self.solver, self.penalty, self.dual)\n",
      "  File \"c:\\Users\\ddaga\\AppData\\Local\\Programs\\Python\\Python39\\lib\\site-packages\\sklearn\\linear_model\\_logistic.py\", line 61, in _check_solver\n",
      "    raise ValueError(\n",
      "ValueError: Solver lbfgs supports only 'l2' or 'none' penalties, got elasticnet penalty.\n",
      "\n",
      "--------------------------------------------------------------------------------\n",
      "10 fits failed with the following error:\n",
      "Traceback (most recent call last):\n",
      "  File \"c:\\Users\\ddaga\\AppData\\Local\\Programs\\Python\\Python39\\lib\\site-packages\\sklearn\\model_selection\\_validation.py\", line 686, in _fit_and_score\n",
      "    estimator.fit(X_train, y_train, **fit_params)\n",
      "  File \"c:\\Users\\ddaga\\AppData\\Local\\Programs\\Python\\Python39\\lib\\site-packages\\sklearn\\linear_model\\_logistic.py\", line 1091, in fit\n",
      "    solver = _check_solver(self.solver, self.penalty, self.dual)\n",
      "  File \"c:\\Users\\ddaga\\AppData\\Local\\Programs\\Python\\Python39\\lib\\site-packages\\sklearn\\linear_model\\_logistic.py\", line 61, in _check_solver\n",
      "    raise ValueError(\n",
      "ValueError: Solver sag supports only 'l2' or 'none' penalties, got elasticnet penalty.\n",
      "\n",
      "--------------------------------------------------------------------------------\n",
      "10 fits failed with the following error:\n",
      "Traceback (most recent call last):\n",
      "  File \"c:\\Users\\ddaga\\AppData\\Local\\Programs\\Python\\Python39\\lib\\site-packages\\sklearn\\model_selection\\_validation.py\", line 686, in _fit_and_score\n",
      "    estimator.fit(X_train, y_train, **fit_params)\n",
      "  File \"c:\\Users\\ddaga\\AppData\\Local\\Programs\\Python\\Python39\\lib\\site-packages\\sklearn\\linear_model\\_logistic.py\", line 1101, in fit\n",
      "    raise ValueError(\n",
      "ValueError: l1_ratio must be between 0 and 1; got (l1_ratio=None)\n",
      "\n",
      "--------------------------------------------------------------------------------\n",
      "50 fits failed with the following error:\n",
      "Traceback (most recent call last):\n",
      "  File \"c:\\Users\\ddaga\\AppData\\Local\\Programs\\Python\\Python39\\lib\\site-packages\\sklearn\\model_selection\\_validation.py\", line 686, in _fit_and_score\n",
      "    estimator.fit(X_train, y_train, **fit_params)\n",
      "  File \"c:\\Users\\ddaga\\AppData\\Local\\Programs\\Python\\Python39\\lib\\site-packages\\sklearn\\linear_model\\_logistic.py\", line 1091, in fit\n",
      "    solver = _check_solver(self.solver, self.penalty, self.dual)\n",
      "  File \"c:\\Users\\ddaga\\AppData\\Local\\Programs\\Python\\Python39\\lib\\site-packages\\sklearn\\linear_model\\_logistic.py\", line 55, in _check_solver\n",
      "    raise ValueError(\n",
      "ValueError: Logistic Regression supports only penalties in ['l1', 'l2', 'elasticnet', 'none'], got None.\n",
      "\n",
      "  warnings.warn(some_fits_failed_message, FitFailedWarning)\n",
      "c:\\Users\\ddaga\\AppData\\Local\\Programs\\Python\\Python39\\lib\\site-packages\\sklearn\\model_selection\\_search.py:953: UserWarning: One or more of the test scores are non-finite: [0.64455556        nan        nan        nan        nan 0.64422222\n",
      " 0.64322222 0.64355556        nan 0.64355556 0.64355556 0.64355556\n",
      "        nan        nan        nan        nan        nan        nan\n",
      "        nan        nan        nan        nan        nan        nan]\n",
      "  warnings.warn(\n",
      "c:\\Users\\ddaga\\AppData\\Local\\Programs\\Python\\Python39\\lib\\site-packages\\sklearn\\linear_model\\_sag.py:350: ConvergenceWarning: The max_iter was reached which means the coef_ did not converge\n",
      "  warnings.warn(\n",
      "c:\\Users\\ddaga\\AppData\\Local\\Programs\\Python\\Python39\\lib\\site-packages\\sklearn\\linear_model\\_sag.py:350: ConvergenceWarning: The max_iter was reached which means the coef_ did not converge\n",
      "  warnings.warn(\n",
      "c:\\Users\\ddaga\\AppData\\Local\\Programs\\Python\\Python39\\lib\\site-packages\\sklearn\\linear_model\\_sag.py:350: ConvergenceWarning: The max_iter was reached which means the coef_ did not converge\n",
      "  warnings.warn(\n",
      "c:\\Users\\ddaga\\AppData\\Local\\Programs\\Python\\Python39\\lib\\site-packages\\sklearn\\linear_model\\_sag.py:350: ConvergenceWarning: The max_iter was reached which means the coef_ did not converge\n",
      "  warnings.warn(\n",
      "c:\\Users\\ddaga\\AppData\\Local\\Programs\\Python\\Python39\\lib\\site-packages\\sklearn\\linear_model\\_sag.py:350: ConvergenceWarning: The max_iter was reached which means the coef_ did not converge\n",
      "  warnings.warn(\n",
      "c:\\Users\\ddaga\\AppData\\Local\\Programs\\Python\\Python39\\lib\\site-packages\\sklearn\\linear_model\\_sag.py:350: ConvergenceWarning: The max_iter was reached which means the coef_ did not converge\n",
      "  warnings.warn(\n",
      "c:\\Users\\ddaga\\AppData\\Local\\Programs\\Python\\Python39\\lib\\site-packages\\sklearn\\linear_model\\_sag.py:350: ConvergenceWarning: The max_iter was reached which means the coef_ did not converge\n",
      "  warnings.warn(\n",
      "c:\\Users\\ddaga\\AppData\\Local\\Programs\\Python\\Python39\\lib\\site-packages\\sklearn\\linear_model\\_sag.py:350: ConvergenceWarning: The max_iter was reached which means the coef_ did not converge\n",
      "  warnings.warn(\n",
      "c:\\Users\\ddaga\\AppData\\Local\\Programs\\Python\\Python39\\lib\\site-packages\\sklearn\\linear_model\\_sag.py:350: ConvergenceWarning: The max_iter was reached which means the coef_ did not converge\n",
      "  warnings.warn(\n",
      "c:\\Users\\ddaga\\AppData\\Local\\Programs\\Python\\Python39\\lib\\site-packages\\sklearn\\model_selection\\_validation.py:378: FitFailedWarning: \n",
      "170 fits failed out of a total of 240.\n",
      "The score on these train-test partitions for these parameters will be set to nan.\n",
      "If these failures are not expected, you can try to debug them by setting error_score='raise'.\n",
      "\n",
      "Below are more details about the failures:\n",
      "--------------------------------------------------------------------------------\n",
      "10 fits failed with the following error:\n",
      "Traceback (most recent call last):\n",
      "  File \"c:\\Users\\ddaga\\AppData\\Local\\Programs\\Python\\Python39\\lib\\site-packages\\sklearn\\model_selection\\_validation.py\", line 686, in _fit_and_score\n",
      "    estimator.fit(X_train, y_train, **fit_params)\n",
      "  File \"c:\\Users\\ddaga\\AppData\\Local\\Programs\\Python\\Python39\\lib\\site-packages\\sklearn\\linear_model\\_logistic.py\", line 1091, in fit\n",
      "    solver = _check_solver(self.solver, self.penalty, self.dual)\n",
      "  File \"c:\\Users\\ddaga\\AppData\\Local\\Programs\\Python\\Python39\\lib\\site-packages\\sklearn\\linear_model\\_logistic.py\", line 61, in _check_solver\n",
      "    raise ValueError(\n",
      "ValueError: Solver newton-cg supports only 'l2' or 'none' penalties, got l1 penalty.\n",
      "\n",
      "--------------------------------------------------------------------------------\n",
      "40 fits failed with the following error:\n",
      "Traceback (most recent call last):\n",
      "  File \"c:\\Users\\ddaga\\AppData\\Local\\Programs\\Python\\Python39\\lib\\site-packages\\sklearn\\model_selection\\_validation.py\", line 686, in _fit_and_score\n",
      "    estimator.fit(X_train, y_train, **fit_params)\n",
      "  File \"c:\\Users\\ddaga\\AppData\\Local\\Programs\\Python\\Python39\\lib\\site-packages\\sklearn\\linear_model\\_logistic.py\", line 1091, in fit\n",
      "    solver = _check_solver(self.solver, self.penalty, self.dual)\n",
      "  File \"c:\\Users\\ddaga\\AppData\\Local\\Programs\\Python\\Python39\\lib\\site-packages\\sklearn\\linear_model\\_logistic.py\", line 48, in _check_solver\n",
      "    raise ValueError(\n",
      "ValueError: Logistic Regression supports only solvers in ['liblinear', 'newton-cg', 'lbfgs', 'sag', 'saga'], got newton-cholesky.\n",
      "\n",
      "--------------------------------------------------------------------------------\n",
      "10 fits failed with the following error:\n",
      "Traceback (most recent call last):\n",
      "  File \"c:\\Users\\ddaga\\AppData\\Local\\Programs\\Python\\Python39\\lib\\site-packages\\sklearn\\model_selection\\_validation.py\", line 686, in _fit_and_score\n",
      "    estimator.fit(X_train, y_train, **fit_params)\n",
      "  File \"c:\\Users\\ddaga\\AppData\\Local\\Programs\\Python\\Python39\\lib\\site-packages\\sklearn\\linear_model\\_logistic.py\", line 1091, in fit\n",
      "    solver = _check_solver(self.solver, self.penalty, self.dual)\n",
      "  File \"c:\\Users\\ddaga\\AppData\\Local\\Programs\\Python\\Python39\\lib\\site-packages\\sklearn\\linear_model\\_logistic.py\", line 61, in _check_solver\n",
      "    raise ValueError(\n",
      "ValueError: Solver lbfgs supports only 'l2' or 'none' penalties, got l1 penalty.\n",
      "\n",
      "--------------------------------------------------------------------------------\n",
      "10 fits failed with the following error:\n",
      "Traceback (most recent call last):\n",
      "  File \"c:\\Users\\ddaga\\AppData\\Local\\Programs\\Python\\Python39\\lib\\site-packages\\sklearn\\model_selection\\_validation.py\", line 686, in _fit_and_score\n",
      "    estimator.fit(X_train, y_train, **fit_params)\n",
      "  File \"c:\\Users\\ddaga\\AppData\\Local\\Programs\\Python\\Python39\\lib\\site-packages\\sklearn\\linear_model\\_logistic.py\", line 1091, in fit\n",
      "    solver = _check_solver(self.solver, self.penalty, self.dual)\n",
      "  File \"c:\\Users\\ddaga\\AppData\\Local\\Programs\\Python\\Python39\\lib\\site-packages\\sklearn\\linear_model\\_logistic.py\", line 61, in _check_solver\n",
      "    raise ValueError(\n",
      "ValueError: Solver sag supports only 'l2' or 'none' penalties, got l1 penalty.\n",
      "\n",
      "--------------------------------------------------------------------------------\n",
      "10 fits failed with the following error:\n",
      "Traceback (most recent call last):\n",
      "  File \"c:\\Users\\ddaga\\AppData\\Local\\Programs\\Python\\Python39\\lib\\site-packages\\sklearn\\model_selection\\_validation.py\", line 686, in _fit_and_score\n",
      "    estimator.fit(X_train, y_train, **fit_params)\n",
      "  File \"c:\\Users\\ddaga\\AppData\\Local\\Programs\\Python\\Python39\\lib\\site-packages\\sklearn\\linear_model\\_logistic.py\", line 1091, in fit\n",
      "    solver = _check_solver(self.solver, self.penalty, self.dual)\n",
      "  File \"c:\\Users\\ddaga\\AppData\\Local\\Programs\\Python\\Python39\\lib\\site-packages\\sklearn\\linear_model\\_logistic.py\", line 71, in _check_solver\n",
      "    raise ValueError(\n",
      "ValueError: Only 'saga' solver supports elasticnet penalty, got solver=liblinear.\n",
      "\n",
      "--------------------------------------------------------------------------------\n",
      "10 fits failed with the following error:\n",
      "Traceback (most recent call last):\n",
      "  File \"c:\\Users\\ddaga\\AppData\\Local\\Programs\\Python\\Python39\\lib\\site-packages\\sklearn\\model_selection\\_validation.py\", line 686, in _fit_and_score\n",
      "    estimator.fit(X_train, y_train, **fit_params)\n",
      "  File \"c:\\Users\\ddaga\\AppData\\Local\\Programs\\Python\\Python39\\lib\\site-packages\\sklearn\\linear_model\\_logistic.py\", line 1091, in fit\n",
      "    solver = _check_solver(self.solver, self.penalty, self.dual)\n",
      "  File \"c:\\Users\\ddaga\\AppData\\Local\\Programs\\Python\\Python39\\lib\\site-packages\\sklearn\\linear_model\\_logistic.py\", line 61, in _check_solver\n",
      "    raise ValueError(\n",
      "ValueError: Solver newton-cg supports only 'l2' or 'none' penalties, got elasticnet penalty.\n",
      "\n",
      "--------------------------------------------------------------------------------\n",
      "10 fits failed with the following error:\n",
      "Traceback (most recent call last):\n",
      "  File \"c:\\Users\\ddaga\\AppData\\Local\\Programs\\Python\\Python39\\lib\\site-packages\\sklearn\\model_selection\\_validation.py\", line 686, in _fit_and_score\n",
      "    estimator.fit(X_train, y_train, **fit_params)\n",
      "  File \"c:\\Users\\ddaga\\AppData\\Local\\Programs\\Python\\Python39\\lib\\site-packages\\sklearn\\linear_model\\_logistic.py\", line 1091, in fit\n",
      "    solver = _check_solver(self.solver, self.penalty, self.dual)\n",
      "  File \"c:\\Users\\ddaga\\AppData\\Local\\Programs\\Python\\Python39\\lib\\site-packages\\sklearn\\linear_model\\_logistic.py\", line 61, in _check_solver\n",
      "    raise ValueError(\n",
      "ValueError: Solver lbfgs supports only 'l2' or 'none' penalties, got elasticnet penalty.\n",
      "\n",
      "--------------------------------------------------------------------------------\n",
      "10 fits failed with the following error:\n",
      "Traceback (most recent call last):\n",
      "  File \"c:\\Users\\ddaga\\AppData\\Local\\Programs\\Python\\Python39\\lib\\site-packages\\sklearn\\model_selection\\_validation.py\", line 686, in _fit_and_score\n",
      "    estimator.fit(X_train, y_train, **fit_params)\n",
      "  File \"c:\\Users\\ddaga\\AppData\\Local\\Programs\\Python\\Python39\\lib\\site-packages\\sklearn\\linear_model\\_logistic.py\", line 1091, in fit\n",
      "    solver = _check_solver(self.solver, self.penalty, self.dual)\n",
      "  File \"c:\\Users\\ddaga\\AppData\\Local\\Programs\\Python\\Python39\\lib\\site-packages\\sklearn\\linear_model\\_logistic.py\", line 61, in _check_solver\n",
      "    raise ValueError(\n",
      "ValueError: Solver sag supports only 'l2' or 'none' penalties, got elasticnet penalty.\n",
      "\n",
      "--------------------------------------------------------------------------------\n",
      "10 fits failed with the following error:\n",
      "Traceback (most recent call last):\n",
      "  File \"c:\\Users\\ddaga\\AppData\\Local\\Programs\\Python\\Python39\\lib\\site-packages\\sklearn\\model_selection\\_validation.py\", line 686, in _fit_and_score\n",
      "    estimator.fit(X_train, y_train, **fit_params)\n",
      "  File \"c:\\Users\\ddaga\\AppData\\Local\\Programs\\Python\\Python39\\lib\\site-packages\\sklearn\\linear_model\\_logistic.py\", line 1101, in fit\n",
      "    raise ValueError(\n",
      "ValueError: l1_ratio must be between 0 and 1; got (l1_ratio=None)\n",
      "\n",
      "--------------------------------------------------------------------------------\n",
      "50 fits failed with the following error:\n",
      "Traceback (most recent call last):\n",
      "  File \"c:\\Users\\ddaga\\AppData\\Local\\Programs\\Python\\Python39\\lib\\site-packages\\sklearn\\model_selection\\_validation.py\", line 686, in _fit_and_score\n",
      "    estimator.fit(X_train, y_train, **fit_params)\n",
      "  File \"c:\\Users\\ddaga\\AppData\\Local\\Programs\\Python\\Python39\\lib\\site-packages\\sklearn\\linear_model\\_logistic.py\", line 1091, in fit\n",
      "    solver = _check_solver(self.solver, self.penalty, self.dual)\n",
      "  File \"c:\\Users\\ddaga\\AppData\\Local\\Programs\\Python\\Python39\\lib\\site-packages\\sklearn\\linear_model\\_logistic.py\", line 55, in _check_solver\n",
      "    raise ValueError(\n",
      "ValueError: Logistic Regression supports only penalties in ['l1', 'l2', 'elasticnet', 'none'], got None.\n",
      "\n",
      "  warnings.warn(some_fits_failed_message, FitFailedWarning)\n",
      "c:\\Users\\ddaga\\AppData\\Local\\Programs\\Python\\Python39\\lib\\site-packages\\sklearn\\model_selection\\_search.py:953: UserWarning: One or more of the test scores are non-finite: [0.64244444        nan        nan        nan        nan 0.64288889\n",
      " 0.64133333 0.64155556        nan 0.64155556 0.64155556 0.64155556\n",
      "        nan        nan        nan        nan        nan        nan\n",
      "        nan        nan        nan        nan        nan        nan]\n",
      "  warnings.warn(\n",
      "c:\\Users\\ddaga\\AppData\\Local\\Programs\\Python\\Python39\\lib\\site-packages\\sklearn\\linear_model\\_sag.py:350: ConvergenceWarning: The max_iter was reached which means the coef_ did not converge\n",
      "  warnings.warn(\n",
      "c:\\Users\\ddaga\\AppData\\Local\\Programs\\Python\\Python39\\lib\\site-packages\\sklearn\\linear_model\\_sag.py:350: ConvergenceWarning: The max_iter was reached which means the coef_ did not converge\n",
      "  warnings.warn(\n",
      "c:\\Users\\ddaga\\AppData\\Local\\Programs\\Python\\Python39\\lib\\site-packages\\sklearn\\linear_model\\_sag.py:350: ConvergenceWarning: The max_iter was reached which means the coef_ did not converge\n",
      "  warnings.warn(\n",
      "c:\\Users\\ddaga\\AppData\\Local\\Programs\\Python\\Python39\\lib\\site-packages\\sklearn\\linear_model\\_sag.py:350: ConvergenceWarning: The max_iter was reached which means the coef_ did not converge\n",
      "  warnings.warn(\n",
      "c:\\Users\\ddaga\\AppData\\Local\\Programs\\Python\\Python39\\lib\\site-packages\\sklearn\\linear_model\\_sag.py:350: ConvergenceWarning: The max_iter was reached which means the coef_ did not converge\n",
      "  warnings.warn(\n",
      "c:\\Users\\ddaga\\AppData\\Local\\Programs\\Python\\Python39\\lib\\site-packages\\sklearn\\linear_model\\_sag.py:350: ConvergenceWarning: The max_iter was reached which means the coef_ did not converge\n",
      "  warnings.warn(\n",
      "c:\\Users\\ddaga\\AppData\\Local\\Programs\\Python\\Python39\\lib\\site-packages\\sklearn\\linear_model\\_sag.py:350: ConvergenceWarning: The max_iter was reached which means the coef_ did not converge\n",
      "  warnings.warn(\n",
      "c:\\Users\\ddaga\\AppData\\Local\\Programs\\Python\\Python39\\lib\\site-packages\\sklearn\\linear_model\\_sag.py:350: ConvergenceWarning: The max_iter was reached which means the coef_ did not converge\n",
      "  warnings.warn(\n",
      "c:\\Users\\ddaga\\AppData\\Local\\Programs\\Python\\Python39\\lib\\site-packages\\sklearn\\linear_model\\_sag.py:350: ConvergenceWarning: The max_iter was reached which means the coef_ did not converge\n",
      "  warnings.warn(\n",
      "c:\\Users\\ddaga\\AppData\\Local\\Programs\\Python\\Python39\\lib\\site-packages\\sklearn\\model_selection\\_validation.py:378: FitFailedWarning: \n",
      "170 fits failed out of a total of 240.\n",
      "The score on these train-test partitions for these parameters will be set to nan.\n",
      "If these failures are not expected, you can try to debug them by setting error_score='raise'.\n",
      "\n",
      "Below are more details about the failures:\n",
      "--------------------------------------------------------------------------------\n",
      "10 fits failed with the following error:\n",
      "Traceback (most recent call last):\n",
      "  File \"c:\\Users\\ddaga\\AppData\\Local\\Programs\\Python\\Python39\\lib\\site-packages\\sklearn\\model_selection\\_validation.py\", line 686, in _fit_and_score\n",
      "    estimator.fit(X_train, y_train, **fit_params)\n",
      "  File \"c:\\Users\\ddaga\\AppData\\Local\\Programs\\Python\\Python39\\lib\\site-packages\\sklearn\\linear_model\\_logistic.py\", line 1091, in fit\n",
      "    solver = _check_solver(self.solver, self.penalty, self.dual)\n",
      "  File \"c:\\Users\\ddaga\\AppData\\Local\\Programs\\Python\\Python39\\lib\\site-packages\\sklearn\\linear_model\\_logistic.py\", line 61, in _check_solver\n",
      "    raise ValueError(\n",
      "ValueError: Solver newton-cg supports only 'l2' or 'none' penalties, got l1 penalty.\n",
      "\n",
      "--------------------------------------------------------------------------------\n",
      "40 fits failed with the following error:\n",
      "Traceback (most recent call last):\n",
      "  File \"c:\\Users\\ddaga\\AppData\\Local\\Programs\\Python\\Python39\\lib\\site-packages\\sklearn\\model_selection\\_validation.py\", line 686, in _fit_and_score\n",
      "    estimator.fit(X_train, y_train, **fit_params)\n",
      "  File \"c:\\Users\\ddaga\\AppData\\Local\\Programs\\Python\\Python39\\lib\\site-packages\\sklearn\\linear_model\\_logistic.py\", line 1091, in fit\n",
      "    solver = _check_solver(self.solver, self.penalty, self.dual)\n",
      "  File \"c:\\Users\\ddaga\\AppData\\Local\\Programs\\Python\\Python39\\lib\\site-packages\\sklearn\\linear_model\\_logistic.py\", line 48, in _check_solver\n",
      "    raise ValueError(\n",
      "ValueError: Logistic Regression supports only solvers in ['liblinear', 'newton-cg', 'lbfgs', 'sag', 'saga'], got newton-cholesky.\n",
      "\n",
      "--------------------------------------------------------------------------------\n",
      "10 fits failed with the following error:\n",
      "Traceback (most recent call last):\n",
      "  File \"c:\\Users\\ddaga\\AppData\\Local\\Programs\\Python\\Python39\\lib\\site-packages\\sklearn\\model_selection\\_validation.py\", line 686, in _fit_and_score\n",
      "    estimator.fit(X_train, y_train, **fit_params)\n",
      "  File \"c:\\Users\\ddaga\\AppData\\Local\\Programs\\Python\\Python39\\lib\\site-packages\\sklearn\\linear_model\\_logistic.py\", line 1091, in fit\n",
      "    solver = _check_solver(self.solver, self.penalty, self.dual)\n",
      "  File \"c:\\Users\\ddaga\\AppData\\Local\\Programs\\Python\\Python39\\lib\\site-packages\\sklearn\\linear_model\\_logistic.py\", line 61, in _check_solver\n",
      "    raise ValueError(\n",
      "ValueError: Solver lbfgs supports only 'l2' or 'none' penalties, got l1 penalty.\n",
      "\n",
      "--------------------------------------------------------------------------------\n",
      "10 fits failed with the following error:\n",
      "Traceback (most recent call last):\n",
      "  File \"c:\\Users\\ddaga\\AppData\\Local\\Programs\\Python\\Python39\\lib\\site-packages\\sklearn\\model_selection\\_validation.py\", line 686, in _fit_and_score\n",
      "    estimator.fit(X_train, y_train, **fit_params)\n",
      "  File \"c:\\Users\\ddaga\\AppData\\Local\\Programs\\Python\\Python39\\lib\\site-packages\\sklearn\\linear_model\\_logistic.py\", line 1091, in fit\n",
      "    solver = _check_solver(self.solver, self.penalty, self.dual)\n",
      "  File \"c:\\Users\\ddaga\\AppData\\Local\\Programs\\Python\\Python39\\lib\\site-packages\\sklearn\\linear_model\\_logistic.py\", line 61, in _check_solver\n",
      "    raise ValueError(\n",
      "ValueError: Solver sag supports only 'l2' or 'none' penalties, got l1 penalty.\n",
      "\n",
      "--------------------------------------------------------------------------------\n",
      "10 fits failed with the following error:\n",
      "Traceback (most recent call last):\n",
      "  File \"c:\\Users\\ddaga\\AppData\\Local\\Programs\\Python\\Python39\\lib\\site-packages\\sklearn\\model_selection\\_validation.py\", line 686, in _fit_and_score\n",
      "    estimator.fit(X_train, y_train, **fit_params)\n",
      "  File \"c:\\Users\\ddaga\\AppData\\Local\\Programs\\Python\\Python39\\lib\\site-packages\\sklearn\\linear_model\\_logistic.py\", line 1091, in fit\n",
      "    solver = _check_solver(self.solver, self.penalty, self.dual)\n",
      "  File \"c:\\Users\\ddaga\\AppData\\Local\\Programs\\Python\\Python39\\lib\\site-packages\\sklearn\\linear_model\\_logistic.py\", line 71, in _check_solver\n",
      "    raise ValueError(\n",
      "ValueError: Only 'saga' solver supports elasticnet penalty, got solver=liblinear.\n",
      "\n",
      "--------------------------------------------------------------------------------\n",
      "10 fits failed with the following error:\n",
      "Traceback (most recent call last):\n",
      "  File \"c:\\Users\\ddaga\\AppData\\Local\\Programs\\Python\\Python39\\lib\\site-packages\\sklearn\\model_selection\\_validation.py\", line 686, in _fit_and_score\n",
      "    estimator.fit(X_train, y_train, **fit_params)\n",
      "  File \"c:\\Users\\ddaga\\AppData\\Local\\Programs\\Python\\Python39\\lib\\site-packages\\sklearn\\linear_model\\_logistic.py\", line 1091, in fit\n",
      "    solver = _check_solver(self.solver, self.penalty, self.dual)\n",
      "  File \"c:\\Users\\ddaga\\AppData\\Local\\Programs\\Python\\Python39\\lib\\site-packages\\sklearn\\linear_model\\_logistic.py\", line 61, in _check_solver\n",
      "    raise ValueError(\n",
      "ValueError: Solver newton-cg supports only 'l2' or 'none' penalties, got elasticnet penalty.\n",
      "\n",
      "--------------------------------------------------------------------------------\n",
      "10 fits failed with the following error:\n",
      "Traceback (most recent call last):\n",
      "  File \"c:\\Users\\ddaga\\AppData\\Local\\Programs\\Python\\Python39\\lib\\site-packages\\sklearn\\model_selection\\_validation.py\", line 686, in _fit_and_score\n",
      "    estimator.fit(X_train, y_train, **fit_params)\n",
      "  File \"c:\\Users\\ddaga\\AppData\\Local\\Programs\\Python\\Python39\\lib\\site-packages\\sklearn\\linear_model\\_logistic.py\", line 1091, in fit\n",
      "    solver = _check_solver(self.solver, self.penalty, self.dual)\n",
      "  File \"c:\\Users\\ddaga\\AppData\\Local\\Programs\\Python\\Python39\\lib\\site-packages\\sklearn\\linear_model\\_logistic.py\", line 61, in _check_solver\n",
      "    raise ValueError(\n",
      "ValueError: Solver lbfgs supports only 'l2' or 'none' penalties, got elasticnet penalty.\n",
      "\n",
      "--------------------------------------------------------------------------------\n",
      "10 fits failed with the following error:\n",
      "Traceback (most recent call last):\n",
      "  File \"c:\\Users\\ddaga\\AppData\\Local\\Programs\\Python\\Python39\\lib\\site-packages\\sklearn\\model_selection\\_validation.py\", line 686, in _fit_and_score\n",
      "    estimator.fit(X_train, y_train, **fit_params)\n",
      "  File \"c:\\Users\\ddaga\\AppData\\Local\\Programs\\Python\\Python39\\lib\\site-packages\\sklearn\\linear_model\\_logistic.py\", line 1091, in fit\n",
      "    solver = _check_solver(self.solver, self.penalty, self.dual)\n",
      "  File \"c:\\Users\\ddaga\\AppData\\Local\\Programs\\Python\\Python39\\lib\\site-packages\\sklearn\\linear_model\\_logistic.py\", line 61, in _check_solver\n",
      "    raise ValueError(\n",
      "ValueError: Solver sag supports only 'l2' or 'none' penalties, got elasticnet penalty.\n",
      "\n",
      "--------------------------------------------------------------------------------\n",
      "10 fits failed with the following error:\n",
      "Traceback (most recent call last):\n",
      "  File \"c:\\Users\\ddaga\\AppData\\Local\\Programs\\Python\\Python39\\lib\\site-packages\\sklearn\\model_selection\\_validation.py\", line 686, in _fit_and_score\n",
      "    estimator.fit(X_train, y_train, **fit_params)\n",
      "  File \"c:\\Users\\ddaga\\AppData\\Local\\Programs\\Python\\Python39\\lib\\site-packages\\sklearn\\linear_model\\_logistic.py\", line 1101, in fit\n",
      "    raise ValueError(\n",
      "ValueError: l1_ratio must be between 0 and 1; got (l1_ratio=None)\n",
      "\n",
      "--------------------------------------------------------------------------------\n",
      "50 fits failed with the following error:\n",
      "Traceback (most recent call last):\n",
      "  File \"c:\\Users\\ddaga\\AppData\\Local\\Programs\\Python\\Python39\\lib\\site-packages\\sklearn\\model_selection\\_validation.py\", line 686, in _fit_and_score\n",
      "    estimator.fit(X_train, y_train, **fit_params)\n",
      "  File \"c:\\Users\\ddaga\\AppData\\Local\\Programs\\Python\\Python39\\lib\\site-packages\\sklearn\\linear_model\\_logistic.py\", line 1091, in fit\n",
      "    solver = _check_solver(self.solver, self.penalty, self.dual)\n",
      "  File \"c:\\Users\\ddaga\\AppData\\Local\\Programs\\Python\\Python39\\lib\\site-packages\\sklearn\\linear_model\\_logistic.py\", line 55, in _check_solver\n",
      "    raise ValueError(\n",
      "ValueError: Logistic Regression supports only penalties in ['l1', 'l2', 'elasticnet', 'none'], got None.\n",
      "\n",
      "  warnings.warn(some_fits_failed_message, FitFailedWarning)\n",
      "c:\\Users\\ddaga\\AppData\\Local\\Programs\\Python\\Python39\\lib\\site-packages\\sklearn\\model_selection\\_search.py:953: UserWarning: One or more of the test scores are non-finite: [0.64288889        nan        nan        nan        nan 0.64255556\n",
      " 0.64188889 0.64177778        nan 0.64177778 0.64166667 0.64166667\n",
      "        nan        nan        nan        nan        nan        nan\n",
      "        nan        nan        nan        nan        nan        nan]\n",
      "  warnings.warn(\n",
      "c:\\Users\\ddaga\\AppData\\Local\\Programs\\Python\\Python39\\lib\\site-packages\\sklearn\\model_selection\\_validation.py:378: FitFailedWarning: \n",
      "170 fits failed out of a total of 240.\n",
      "The score on these train-test partitions for these parameters will be set to nan.\n",
      "If these failures are not expected, you can try to debug them by setting error_score='raise'.\n",
      "\n",
      "Below are more details about the failures:\n",
      "--------------------------------------------------------------------------------\n",
      "10 fits failed with the following error:\n",
      "Traceback (most recent call last):\n",
      "  File \"c:\\Users\\ddaga\\AppData\\Local\\Programs\\Python\\Python39\\lib\\site-packages\\sklearn\\model_selection\\_validation.py\", line 686, in _fit_and_score\n",
      "    estimator.fit(X_train, y_train, **fit_params)\n",
      "  File \"c:\\Users\\ddaga\\AppData\\Local\\Programs\\Python\\Python39\\lib\\site-packages\\sklearn\\linear_model\\_logistic.py\", line 1091, in fit\n",
      "    solver = _check_solver(self.solver, self.penalty, self.dual)\n",
      "  File \"c:\\Users\\ddaga\\AppData\\Local\\Programs\\Python\\Python39\\lib\\site-packages\\sklearn\\linear_model\\_logistic.py\", line 61, in _check_solver\n",
      "    raise ValueError(\n",
      "ValueError: Solver newton-cg supports only 'l2' or 'none' penalties, got l1 penalty.\n",
      "\n",
      "--------------------------------------------------------------------------------\n",
      "40 fits failed with the following error:\n",
      "Traceback (most recent call last):\n",
      "  File \"c:\\Users\\ddaga\\AppData\\Local\\Programs\\Python\\Python39\\lib\\site-packages\\sklearn\\model_selection\\_validation.py\", line 686, in _fit_and_score\n",
      "    estimator.fit(X_train, y_train, **fit_params)\n",
      "  File \"c:\\Users\\ddaga\\AppData\\Local\\Programs\\Python\\Python39\\lib\\site-packages\\sklearn\\linear_model\\_logistic.py\", line 1091, in fit\n",
      "    solver = _check_solver(self.solver, self.penalty, self.dual)\n",
      "  File \"c:\\Users\\ddaga\\AppData\\Local\\Programs\\Python\\Python39\\lib\\site-packages\\sklearn\\linear_model\\_logistic.py\", line 48, in _check_solver\n",
      "    raise ValueError(\n",
      "ValueError: Logistic Regression supports only solvers in ['liblinear', 'newton-cg', 'lbfgs', 'sag', 'saga'], got newton-cholesky.\n",
      "\n",
      "--------------------------------------------------------------------------------\n",
      "10 fits failed with the following error:\n",
      "Traceback (most recent call last):\n",
      "  File \"c:\\Users\\ddaga\\AppData\\Local\\Programs\\Python\\Python39\\lib\\site-packages\\sklearn\\model_selection\\_validation.py\", line 686, in _fit_and_score\n",
      "    estimator.fit(X_train, y_train, **fit_params)\n",
      "  File \"c:\\Users\\ddaga\\AppData\\Local\\Programs\\Python\\Python39\\lib\\site-packages\\sklearn\\linear_model\\_logistic.py\", line 1091, in fit\n",
      "    solver = _check_solver(self.solver, self.penalty, self.dual)\n",
      "  File \"c:\\Users\\ddaga\\AppData\\Local\\Programs\\Python\\Python39\\lib\\site-packages\\sklearn\\linear_model\\_logistic.py\", line 61, in _check_solver\n",
      "    raise ValueError(\n",
      "ValueError: Solver lbfgs supports only 'l2' or 'none' penalties, got l1 penalty.\n",
      "\n",
      "--------------------------------------------------------------------------------\n",
      "10 fits failed with the following error:\n",
      "Traceback (most recent call last):\n",
      "  File \"c:\\Users\\ddaga\\AppData\\Local\\Programs\\Python\\Python39\\lib\\site-packages\\sklearn\\model_selection\\_validation.py\", line 686, in _fit_and_score\n",
      "    estimator.fit(X_train, y_train, **fit_params)\n",
      "  File \"c:\\Users\\ddaga\\AppData\\Local\\Programs\\Python\\Python39\\lib\\site-packages\\sklearn\\linear_model\\_logistic.py\", line 1091, in fit\n",
      "    solver = _check_solver(self.solver, self.penalty, self.dual)\n",
      "  File \"c:\\Users\\ddaga\\AppData\\Local\\Programs\\Python\\Python39\\lib\\site-packages\\sklearn\\linear_model\\_logistic.py\", line 61, in _check_solver\n",
      "    raise ValueError(\n",
      "ValueError: Solver sag supports only 'l2' or 'none' penalties, got l1 penalty.\n",
      "\n",
      "--------------------------------------------------------------------------------\n",
      "10 fits failed with the following error:\n",
      "Traceback (most recent call last):\n",
      "  File \"c:\\Users\\ddaga\\AppData\\Local\\Programs\\Python\\Python39\\lib\\site-packages\\sklearn\\model_selection\\_validation.py\", line 686, in _fit_and_score\n",
      "    estimator.fit(X_train, y_train, **fit_params)\n",
      "  File \"c:\\Users\\ddaga\\AppData\\Local\\Programs\\Python\\Python39\\lib\\site-packages\\sklearn\\linear_model\\_logistic.py\", line 1091, in fit\n",
      "    solver = _check_solver(self.solver, self.penalty, self.dual)\n",
      "  File \"c:\\Users\\ddaga\\AppData\\Local\\Programs\\Python\\Python39\\lib\\site-packages\\sklearn\\linear_model\\_logistic.py\", line 71, in _check_solver\n",
      "    raise ValueError(\n",
      "ValueError: Only 'saga' solver supports elasticnet penalty, got solver=liblinear.\n",
      "\n",
      "--------------------------------------------------------------------------------\n",
      "10 fits failed with the following error:\n",
      "Traceback (most recent call last):\n",
      "  File \"c:\\Users\\ddaga\\AppData\\Local\\Programs\\Python\\Python39\\lib\\site-packages\\sklearn\\model_selection\\_validation.py\", line 686, in _fit_and_score\n",
      "    estimator.fit(X_train, y_train, **fit_params)\n",
      "  File \"c:\\Users\\ddaga\\AppData\\Local\\Programs\\Python\\Python39\\lib\\site-packages\\sklearn\\linear_model\\_logistic.py\", line 1091, in fit\n",
      "    solver = _check_solver(self.solver, self.penalty, self.dual)\n",
      "  File \"c:\\Users\\ddaga\\AppData\\Local\\Programs\\Python\\Python39\\lib\\site-packages\\sklearn\\linear_model\\_logistic.py\", line 61, in _check_solver\n",
      "    raise ValueError(\n",
      "ValueError: Solver newton-cg supports only 'l2' or 'none' penalties, got elasticnet penalty.\n",
      "\n",
      "--------------------------------------------------------------------------------\n",
      "10 fits failed with the following error:\n",
      "Traceback (most recent call last):\n",
      "  File \"c:\\Users\\ddaga\\AppData\\Local\\Programs\\Python\\Python39\\lib\\site-packages\\sklearn\\model_selection\\_validation.py\", line 686, in _fit_and_score\n",
      "    estimator.fit(X_train, y_train, **fit_params)\n",
      "  File \"c:\\Users\\ddaga\\AppData\\Local\\Programs\\Python\\Python39\\lib\\site-packages\\sklearn\\linear_model\\_logistic.py\", line 1091, in fit\n",
      "    solver = _check_solver(self.solver, self.penalty, self.dual)\n",
      "  File \"c:\\Users\\ddaga\\AppData\\Local\\Programs\\Python\\Python39\\lib\\site-packages\\sklearn\\linear_model\\_logistic.py\", line 61, in _check_solver\n",
      "    raise ValueError(\n",
      "ValueError: Solver lbfgs supports only 'l2' or 'none' penalties, got elasticnet penalty.\n",
      "\n",
      "--------------------------------------------------------------------------------\n",
      "10 fits failed with the following error:\n",
      "Traceback (most recent call last):\n",
      "  File \"c:\\Users\\ddaga\\AppData\\Local\\Programs\\Python\\Python39\\lib\\site-packages\\sklearn\\model_selection\\_validation.py\", line 686, in _fit_and_score\n",
      "    estimator.fit(X_train, y_train, **fit_params)\n",
      "  File \"c:\\Users\\ddaga\\AppData\\Local\\Programs\\Python\\Python39\\lib\\site-packages\\sklearn\\linear_model\\_logistic.py\", line 1091, in fit\n",
      "    solver = _check_solver(self.solver, self.penalty, self.dual)\n",
      "  File \"c:\\Users\\ddaga\\AppData\\Local\\Programs\\Python\\Python39\\lib\\site-packages\\sklearn\\linear_model\\_logistic.py\", line 61, in _check_solver\n",
      "    raise ValueError(\n",
      "ValueError: Solver sag supports only 'l2' or 'none' penalties, got elasticnet penalty.\n",
      "\n",
      "--------------------------------------------------------------------------------\n",
      "10 fits failed with the following error:\n",
      "Traceback (most recent call last):\n",
      "  File \"c:\\Users\\ddaga\\AppData\\Local\\Programs\\Python\\Python39\\lib\\site-packages\\sklearn\\model_selection\\_validation.py\", line 686, in _fit_and_score\n",
      "    estimator.fit(X_train, y_train, **fit_params)\n",
      "  File \"c:\\Users\\ddaga\\AppData\\Local\\Programs\\Python\\Python39\\lib\\site-packages\\sklearn\\linear_model\\_logistic.py\", line 1101, in fit\n",
      "    raise ValueError(\n",
      "ValueError: l1_ratio must be between 0 and 1; got (l1_ratio=None)\n",
      "\n",
      "--------------------------------------------------------------------------------\n",
      "50 fits failed with the following error:\n",
      "Traceback (most recent call last):\n",
      "  File \"c:\\Users\\ddaga\\AppData\\Local\\Programs\\Python\\Python39\\lib\\site-packages\\sklearn\\model_selection\\_validation.py\", line 686, in _fit_and_score\n",
      "    estimator.fit(X_train, y_train, **fit_params)\n",
      "  File \"c:\\Users\\ddaga\\AppData\\Local\\Programs\\Python\\Python39\\lib\\site-packages\\sklearn\\linear_model\\_logistic.py\", line 1091, in fit\n",
      "    solver = _check_solver(self.solver, self.penalty, self.dual)\n",
      "  File \"c:\\Users\\ddaga\\AppData\\Local\\Programs\\Python\\Python39\\lib\\site-packages\\sklearn\\linear_model\\_logistic.py\", line 55, in _check_solver\n",
      "    raise ValueError(\n",
      "ValueError: Logistic Regression supports only penalties in ['l1', 'l2', 'elasticnet', 'none'], got None.\n",
      "\n",
      "  warnings.warn(some_fits_failed_message, FitFailedWarning)\n",
      "c:\\Users\\ddaga\\AppData\\Local\\Programs\\Python\\Python39\\lib\\site-packages\\sklearn\\model_selection\\_search.py:953: UserWarning: One or more of the test scores are non-finite: [0.64733333        nan        nan        nan        nan 0.64788889\n",
      " 0.64577778 0.64577778        nan 0.64577778 0.64577778 0.64577778\n",
      "        nan        nan        nan        nan        nan        nan\n",
      "        nan        nan        nan        nan        nan        nan]\n",
      "  warnings.warn(\n",
      "c:\\Users\\ddaga\\AppData\\Local\\Programs\\Python\\Python39\\lib\\site-packages\\sklearn\\linear_model\\_sag.py:350: ConvergenceWarning: The max_iter was reached which means the coef_ did not converge\n",
      "  warnings.warn(\n",
      "c:\\Users\\ddaga\\AppData\\Local\\Programs\\Python\\Python39\\lib\\site-packages\\sklearn\\linear_model\\_sag.py:350: ConvergenceWarning: The max_iter was reached which means the coef_ did not converge\n",
      "  warnings.warn(\n",
      "c:\\Users\\ddaga\\AppData\\Local\\Programs\\Python\\Python39\\lib\\site-packages\\sklearn\\linear_model\\_sag.py:350: ConvergenceWarning: The max_iter was reached which means the coef_ did not converge\n",
      "  warnings.warn(\n",
      "c:\\Users\\ddaga\\AppData\\Local\\Programs\\Python\\Python39\\lib\\site-packages\\sklearn\\linear_model\\_sag.py:350: ConvergenceWarning: The max_iter was reached which means the coef_ did not converge\n",
      "  warnings.warn(\n",
      "c:\\Users\\ddaga\\AppData\\Local\\Programs\\Python\\Python39\\lib\\site-packages\\sklearn\\linear_model\\_sag.py:350: ConvergenceWarning: The max_iter was reached which means the coef_ did not converge\n",
      "  warnings.warn(\n",
      "c:\\Users\\ddaga\\AppData\\Local\\Programs\\Python\\Python39\\lib\\site-packages\\sklearn\\linear_model\\_sag.py:350: ConvergenceWarning: The max_iter was reached which means the coef_ did not converge\n",
      "  warnings.warn(\n",
      "c:\\Users\\ddaga\\AppData\\Local\\Programs\\Python\\Python39\\lib\\site-packages\\sklearn\\linear_model\\_sag.py:350: ConvergenceWarning: The max_iter was reached which means the coef_ did not converge\n",
      "  warnings.warn(\n",
      "c:\\Users\\ddaga\\AppData\\Local\\Programs\\Python\\Python39\\lib\\site-packages\\sklearn\\linear_model\\_sag.py:350: ConvergenceWarning: The max_iter was reached which means the coef_ did not converge\n",
      "  warnings.warn(\n",
      "c:\\Users\\ddaga\\AppData\\Local\\Programs\\Python\\Python39\\lib\\site-packages\\sklearn\\linear_model\\_sag.py:350: ConvergenceWarning: The max_iter was reached which means the coef_ did not converge\n",
      "  warnings.warn(\n",
      "c:\\Users\\ddaga\\AppData\\Local\\Programs\\Python\\Python39\\lib\\site-packages\\sklearn\\model_selection\\_validation.py:378: FitFailedWarning: \n",
      "170 fits failed out of a total of 240.\n",
      "The score on these train-test partitions for these parameters will be set to nan.\n",
      "If these failures are not expected, you can try to debug them by setting error_score='raise'.\n",
      "\n",
      "Below are more details about the failures:\n",
      "--------------------------------------------------------------------------------\n",
      "10 fits failed with the following error:\n",
      "Traceback (most recent call last):\n",
      "  File \"c:\\Users\\ddaga\\AppData\\Local\\Programs\\Python\\Python39\\lib\\site-packages\\sklearn\\model_selection\\_validation.py\", line 686, in _fit_and_score\n",
      "    estimator.fit(X_train, y_train, **fit_params)\n",
      "  File \"c:\\Users\\ddaga\\AppData\\Local\\Programs\\Python\\Python39\\lib\\site-packages\\sklearn\\linear_model\\_logistic.py\", line 1091, in fit\n",
      "    solver = _check_solver(self.solver, self.penalty, self.dual)\n",
      "  File \"c:\\Users\\ddaga\\AppData\\Local\\Programs\\Python\\Python39\\lib\\site-packages\\sklearn\\linear_model\\_logistic.py\", line 61, in _check_solver\n",
      "    raise ValueError(\n",
      "ValueError: Solver newton-cg supports only 'l2' or 'none' penalties, got l1 penalty.\n",
      "\n",
      "--------------------------------------------------------------------------------\n",
      "40 fits failed with the following error:\n",
      "Traceback (most recent call last):\n",
      "  File \"c:\\Users\\ddaga\\AppData\\Local\\Programs\\Python\\Python39\\lib\\site-packages\\sklearn\\model_selection\\_validation.py\", line 686, in _fit_and_score\n",
      "    estimator.fit(X_train, y_train, **fit_params)\n",
      "  File \"c:\\Users\\ddaga\\AppData\\Local\\Programs\\Python\\Python39\\lib\\site-packages\\sklearn\\linear_model\\_logistic.py\", line 1091, in fit\n",
      "    solver = _check_solver(self.solver, self.penalty, self.dual)\n",
      "  File \"c:\\Users\\ddaga\\AppData\\Local\\Programs\\Python\\Python39\\lib\\site-packages\\sklearn\\linear_model\\_logistic.py\", line 48, in _check_solver\n",
      "    raise ValueError(\n",
      "ValueError: Logistic Regression supports only solvers in ['liblinear', 'newton-cg', 'lbfgs', 'sag', 'saga'], got newton-cholesky.\n",
      "\n",
      "--------------------------------------------------------------------------------\n",
      "10 fits failed with the following error:\n",
      "Traceback (most recent call last):\n",
      "  File \"c:\\Users\\ddaga\\AppData\\Local\\Programs\\Python\\Python39\\lib\\site-packages\\sklearn\\model_selection\\_validation.py\", line 686, in _fit_and_score\n",
      "    estimator.fit(X_train, y_train, **fit_params)\n",
      "  File \"c:\\Users\\ddaga\\AppData\\Local\\Programs\\Python\\Python39\\lib\\site-packages\\sklearn\\linear_model\\_logistic.py\", line 1091, in fit\n",
      "    solver = _check_solver(self.solver, self.penalty, self.dual)\n",
      "  File \"c:\\Users\\ddaga\\AppData\\Local\\Programs\\Python\\Python39\\lib\\site-packages\\sklearn\\linear_model\\_logistic.py\", line 61, in _check_solver\n",
      "    raise ValueError(\n",
      "ValueError: Solver lbfgs supports only 'l2' or 'none' penalties, got l1 penalty.\n",
      "\n",
      "--------------------------------------------------------------------------------\n",
      "10 fits failed with the following error:\n",
      "Traceback (most recent call last):\n",
      "  File \"c:\\Users\\ddaga\\AppData\\Local\\Programs\\Python\\Python39\\lib\\site-packages\\sklearn\\model_selection\\_validation.py\", line 686, in _fit_and_score\n",
      "    estimator.fit(X_train, y_train, **fit_params)\n",
      "  File \"c:\\Users\\ddaga\\AppData\\Local\\Programs\\Python\\Python39\\lib\\site-packages\\sklearn\\linear_model\\_logistic.py\", line 1091, in fit\n",
      "    solver = _check_solver(self.solver, self.penalty, self.dual)\n",
      "  File \"c:\\Users\\ddaga\\AppData\\Local\\Programs\\Python\\Python39\\lib\\site-packages\\sklearn\\linear_model\\_logistic.py\", line 61, in _check_solver\n",
      "    raise ValueError(\n",
      "ValueError: Solver sag supports only 'l2' or 'none' penalties, got l1 penalty.\n",
      "\n",
      "--------------------------------------------------------------------------------\n",
      "10 fits failed with the following error:\n",
      "Traceback (most recent call last):\n",
      "  File \"c:\\Users\\ddaga\\AppData\\Local\\Programs\\Python\\Python39\\lib\\site-packages\\sklearn\\model_selection\\_validation.py\", line 686, in _fit_and_score\n",
      "    estimator.fit(X_train, y_train, **fit_params)\n",
      "  File \"c:\\Users\\ddaga\\AppData\\Local\\Programs\\Python\\Python39\\lib\\site-packages\\sklearn\\linear_model\\_logistic.py\", line 1091, in fit\n",
      "    solver = _check_solver(self.solver, self.penalty, self.dual)\n",
      "  File \"c:\\Users\\ddaga\\AppData\\Local\\Programs\\Python\\Python39\\lib\\site-packages\\sklearn\\linear_model\\_logistic.py\", line 71, in _check_solver\n",
      "    raise ValueError(\n",
      "ValueError: Only 'saga' solver supports elasticnet penalty, got solver=liblinear.\n",
      "\n",
      "--------------------------------------------------------------------------------\n",
      "10 fits failed with the following error:\n",
      "Traceback (most recent call last):\n",
      "  File \"c:\\Users\\ddaga\\AppData\\Local\\Programs\\Python\\Python39\\lib\\site-packages\\sklearn\\model_selection\\_validation.py\", line 686, in _fit_and_score\n",
      "    estimator.fit(X_train, y_train, **fit_params)\n",
      "  File \"c:\\Users\\ddaga\\AppData\\Local\\Programs\\Python\\Python39\\lib\\site-packages\\sklearn\\linear_model\\_logistic.py\", line 1091, in fit\n",
      "    solver = _check_solver(self.solver, self.penalty, self.dual)\n",
      "  File \"c:\\Users\\ddaga\\AppData\\Local\\Programs\\Python\\Python39\\lib\\site-packages\\sklearn\\linear_model\\_logistic.py\", line 61, in _check_solver\n",
      "    raise ValueError(\n",
      "ValueError: Solver newton-cg supports only 'l2' or 'none' penalties, got elasticnet penalty.\n",
      "\n",
      "--------------------------------------------------------------------------------\n",
      "10 fits failed with the following error:\n",
      "Traceback (most recent call last):\n",
      "  File \"c:\\Users\\ddaga\\AppData\\Local\\Programs\\Python\\Python39\\lib\\site-packages\\sklearn\\model_selection\\_validation.py\", line 686, in _fit_and_score\n",
      "    estimator.fit(X_train, y_train, **fit_params)\n",
      "  File \"c:\\Users\\ddaga\\AppData\\Local\\Programs\\Python\\Python39\\lib\\site-packages\\sklearn\\linear_model\\_logistic.py\", line 1091, in fit\n",
      "    solver = _check_solver(self.solver, self.penalty, self.dual)\n",
      "  File \"c:\\Users\\ddaga\\AppData\\Local\\Programs\\Python\\Python39\\lib\\site-packages\\sklearn\\linear_model\\_logistic.py\", line 61, in _check_solver\n",
      "    raise ValueError(\n",
      "ValueError: Solver lbfgs supports only 'l2' or 'none' penalties, got elasticnet penalty.\n",
      "\n",
      "--------------------------------------------------------------------------------\n",
      "10 fits failed with the following error:\n",
      "Traceback (most recent call last):\n",
      "  File \"c:\\Users\\ddaga\\AppData\\Local\\Programs\\Python\\Python39\\lib\\site-packages\\sklearn\\model_selection\\_validation.py\", line 686, in _fit_and_score\n",
      "    estimator.fit(X_train, y_train, **fit_params)\n",
      "  File \"c:\\Users\\ddaga\\AppData\\Local\\Programs\\Python\\Python39\\lib\\site-packages\\sklearn\\linear_model\\_logistic.py\", line 1091, in fit\n",
      "    solver = _check_solver(self.solver, self.penalty, self.dual)\n",
      "  File \"c:\\Users\\ddaga\\AppData\\Local\\Programs\\Python\\Python39\\lib\\site-packages\\sklearn\\linear_model\\_logistic.py\", line 61, in _check_solver\n",
      "    raise ValueError(\n",
      "ValueError: Solver sag supports only 'l2' or 'none' penalties, got elasticnet penalty.\n",
      "\n",
      "--------------------------------------------------------------------------------\n",
      "10 fits failed with the following error:\n",
      "Traceback (most recent call last):\n",
      "  File \"c:\\Users\\ddaga\\AppData\\Local\\Programs\\Python\\Python39\\lib\\site-packages\\sklearn\\model_selection\\_validation.py\", line 686, in _fit_and_score\n",
      "    estimator.fit(X_train, y_train, **fit_params)\n",
      "  File \"c:\\Users\\ddaga\\AppData\\Local\\Programs\\Python\\Python39\\lib\\site-packages\\sklearn\\linear_model\\_logistic.py\", line 1101, in fit\n",
      "    raise ValueError(\n",
      "ValueError: l1_ratio must be between 0 and 1; got (l1_ratio=None)\n",
      "\n",
      "--------------------------------------------------------------------------------\n",
      "50 fits failed with the following error:\n",
      "Traceback (most recent call last):\n",
      "  File \"c:\\Users\\ddaga\\AppData\\Local\\Programs\\Python\\Python39\\lib\\site-packages\\sklearn\\model_selection\\_validation.py\", line 686, in _fit_and_score\n",
      "    estimator.fit(X_train, y_train, **fit_params)\n",
      "  File \"c:\\Users\\ddaga\\AppData\\Local\\Programs\\Python\\Python39\\lib\\site-packages\\sklearn\\linear_model\\_logistic.py\", line 1091, in fit\n",
      "    solver = _check_solver(self.solver, self.penalty, self.dual)\n",
      "  File \"c:\\Users\\ddaga\\AppData\\Local\\Programs\\Python\\Python39\\lib\\site-packages\\sklearn\\linear_model\\_logistic.py\", line 55, in _check_solver\n",
      "    raise ValueError(\n",
      "ValueError: Logistic Regression supports only penalties in ['l1', 'l2', 'elasticnet', 'none'], got None.\n",
      "\n",
      "  warnings.warn(some_fits_failed_message, FitFailedWarning)\n",
      "c:\\Users\\ddaga\\AppData\\Local\\Programs\\Python\\Python39\\lib\\site-packages\\sklearn\\model_selection\\_search.py:953: UserWarning: One or more of the test scores are non-finite: [0.64422222        nan        nan        nan        nan 0.64388889\n",
      " 0.64266667 0.64266667        nan 0.64266667 0.64266667 0.64255556\n",
      "        nan        nan        nan        nan        nan        nan\n",
      "        nan        nan        nan        nan        nan        nan]\n",
      "  warnings.warn(\n",
      "c:\\Users\\ddaga\\AppData\\Local\\Programs\\Python\\Python39\\lib\\site-packages\\sklearn\\linear_model\\_sag.py:350: ConvergenceWarning: The max_iter was reached which means the coef_ did not converge\n",
      "  warnings.warn(\n",
      "c:\\Users\\ddaga\\AppData\\Local\\Programs\\Python\\Python39\\lib\\site-packages\\sklearn\\linear_model\\_sag.py:350: ConvergenceWarning: The max_iter was reached which means the coef_ did not converge\n",
      "  warnings.warn(\n",
      "c:\\Users\\ddaga\\AppData\\Local\\Programs\\Python\\Python39\\lib\\site-packages\\sklearn\\linear_model\\_sag.py:350: ConvergenceWarning: The max_iter was reached which means the coef_ did not converge\n",
      "  warnings.warn(\n",
      "c:\\Users\\ddaga\\AppData\\Local\\Programs\\Python\\Python39\\lib\\site-packages\\sklearn\\linear_model\\_sag.py:350: ConvergenceWarning: The max_iter was reached which means the coef_ did not converge\n",
      "  warnings.warn(\n",
      "c:\\Users\\ddaga\\AppData\\Local\\Programs\\Python\\Python39\\lib\\site-packages\\sklearn\\linear_model\\_sag.py:350: ConvergenceWarning: The max_iter was reached which means the coef_ did not converge\n",
      "  warnings.warn(\n",
      "c:\\Users\\ddaga\\AppData\\Local\\Programs\\Python\\Python39\\lib\\site-packages\\sklearn\\linear_model\\_sag.py:350: ConvergenceWarning: The max_iter was reached which means the coef_ did not converge\n",
      "  warnings.warn(\n",
      "c:\\Users\\ddaga\\AppData\\Local\\Programs\\Python\\Python39\\lib\\site-packages\\sklearn\\linear_model\\_sag.py:350: ConvergenceWarning: The max_iter was reached which means the coef_ did not converge\n",
      "  warnings.warn(\n",
      "c:\\Users\\ddaga\\AppData\\Local\\Programs\\Python\\Python39\\lib\\site-packages\\sklearn\\linear_model\\_sag.py:350: ConvergenceWarning: The max_iter was reached which means the coef_ did not converge\n",
      "  warnings.warn(\n",
      "c:\\Users\\ddaga\\AppData\\Local\\Programs\\Python\\Python39\\lib\\site-packages\\sklearn\\linear_model\\_sag.py:350: ConvergenceWarning: The max_iter was reached which means the coef_ did not converge\n",
      "  warnings.warn(\n",
      "c:\\Users\\ddaga\\AppData\\Local\\Programs\\Python\\Python39\\lib\\site-packages\\sklearn\\model_selection\\_validation.py:378: FitFailedWarning: \n",
      "170 fits failed out of a total of 240.\n",
      "The score on these train-test partitions for these parameters will be set to nan.\n",
      "If these failures are not expected, you can try to debug them by setting error_score='raise'.\n",
      "\n",
      "Below are more details about the failures:\n",
      "--------------------------------------------------------------------------------\n",
      "10 fits failed with the following error:\n",
      "Traceback (most recent call last):\n",
      "  File \"c:\\Users\\ddaga\\AppData\\Local\\Programs\\Python\\Python39\\lib\\site-packages\\sklearn\\model_selection\\_validation.py\", line 686, in _fit_and_score\n",
      "    estimator.fit(X_train, y_train, **fit_params)\n",
      "  File \"c:\\Users\\ddaga\\AppData\\Local\\Programs\\Python\\Python39\\lib\\site-packages\\sklearn\\linear_model\\_logistic.py\", line 1091, in fit\n",
      "    solver = _check_solver(self.solver, self.penalty, self.dual)\n",
      "  File \"c:\\Users\\ddaga\\AppData\\Local\\Programs\\Python\\Python39\\lib\\site-packages\\sklearn\\linear_model\\_logistic.py\", line 61, in _check_solver\n",
      "    raise ValueError(\n",
      "ValueError: Solver newton-cg supports only 'l2' or 'none' penalties, got l1 penalty.\n",
      "\n",
      "--------------------------------------------------------------------------------\n",
      "40 fits failed with the following error:\n",
      "Traceback (most recent call last):\n",
      "  File \"c:\\Users\\ddaga\\AppData\\Local\\Programs\\Python\\Python39\\lib\\site-packages\\sklearn\\model_selection\\_validation.py\", line 686, in _fit_and_score\n",
      "    estimator.fit(X_train, y_train, **fit_params)\n",
      "  File \"c:\\Users\\ddaga\\AppData\\Local\\Programs\\Python\\Python39\\lib\\site-packages\\sklearn\\linear_model\\_logistic.py\", line 1091, in fit\n",
      "    solver = _check_solver(self.solver, self.penalty, self.dual)\n",
      "  File \"c:\\Users\\ddaga\\AppData\\Local\\Programs\\Python\\Python39\\lib\\site-packages\\sklearn\\linear_model\\_logistic.py\", line 48, in _check_solver\n",
      "    raise ValueError(\n",
      "ValueError: Logistic Regression supports only solvers in ['liblinear', 'newton-cg', 'lbfgs', 'sag', 'saga'], got newton-cholesky.\n",
      "\n",
      "--------------------------------------------------------------------------------\n",
      "10 fits failed with the following error:\n",
      "Traceback (most recent call last):\n",
      "  File \"c:\\Users\\ddaga\\AppData\\Local\\Programs\\Python\\Python39\\lib\\site-packages\\sklearn\\model_selection\\_validation.py\", line 686, in _fit_and_score\n",
      "    estimator.fit(X_train, y_train, **fit_params)\n",
      "  File \"c:\\Users\\ddaga\\AppData\\Local\\Programs\\Python\\Python39\\lib\\site-packages\\sklearn\\linear_model\\_logistic.py\", line 1091, in fit\n",
      "    solver = _check_solver(self.solver, self.penalty, self.dual)\n",
      "  File \"c:\\Users\\ddaga\\AppData\\Local\\Programs\\Python\\Python39\\lib\\site-packages\\sklearn\\linear_model\\_logistic.py\", line 61, in _check_solver\n",
      "    raise ValueError(\n",
      "ValueError: Solver lbfgs supports only 'l2' or 'none' penalties, got l1 penalty.\n",
      "\n",
      "--------------------------------------------------------------------------------\n",
      "10 fits failed with the following error:\n",
      "Traceback (most recent call last):\n",
      "  File \"c:\\Users\\ddaga\\AppData\\Local\\Programs\\Python\\Python39\\lib\\site-packages\\sklearn\\model_selection\\_validation.py\", line 686, in _fit_and_score\n",
      "    estimator.fit(X_train, y_train, **fit_params)\n",
      "  File \"c:\\Users\\ddaga\\AppData\\Local\\Programs\\Python\\Python39\\lib\\site-packages\\sklearn\\linear_model\\_logistic.py\", line 1091, in fit\n",
      "    solver = _check_solver(self.solver, self.penalty, self.dual)\n",
      "  File \"c:\\Users\\ddaga\\AppData\\Local\\Programs\\Python\\Python39\\lib\\site-packages\\sklearn\\linear_model\\_logistic.py\", line 61, in _check_solver\n",
      "    raise ValueError(\n",
      "ValueError: Solver sag supports only 'l2' or 'none' penalties, got l1 penalty.\n",
      "\n",
      "--------------------------------------------------------------------------------\n",
      "10 fits failed with the following error:\n",
      "Traceback (most recent call last):\n",
      "  File \"c:\\Users\\ddaga\\AppData\\Local\\Programs\\Python\\Python39\\lib\\site-packages\\sklearn\\model_selection\\_validation.py\", line 686, in _fit_and_score\n",
      "    estimator.fit(X_train, y_train, **fit_params)\n",
      "  File \"c:\\Users\\ddaga\\AppData\\Local\\Programs\\Python\\Python39\\lib\\site-packages\\sklearn\\linear_model\\_logistic.py\", line 1091, in fit\n",
      "    solver = _check_solver(self.solver, self.penalty, self.dual)\n",
      "  File \"c:\\Users\\ddaga\\AppData\\Local\\Programs\\Python\\Python39\\lib\\site-packages\\sklearn\\linear_model\\_logistic.py\", line 71, in _check_solver\n",
      "    raise ValueError(\n",
      "ValueError: Only 'saga' solver supports elasticnet penalty, got solver=liblinear.\n",
      "\n",
      "--------------------------------------------------------------------------------\n",
      "10 fits failed with the following error:\n",
      "Traceback (most recent call last):\n",
      "  File \"c:\\Users\\ddaga\\AppData\\Local\\Programs\\Python\\Python39\\lib\\site-packages\\sklearn\\model_selection\\_validation.py\", line 686, in _fit_and_score\n",
      "    estimator.fit(X_train, y_train, **fit_params)\n",
      "  File \"c:\\Users\\ddaga\\AppData\\Local\\Programs\\Python\\Python39\\lib\\site-packages\\sklearn\\linear_model\\_logistic.py\", line 1091, in fit\n",
      "    solver = _check_solver(self.solver, self.penalty, self.dual)\n",
      "  File \"c:\\Users\\ddaga\\AppData\\Local\\Programs\\Python\\Python39\\lib\\site-packages\\sklearn\\linear_model\\_logistic.py\", line 61, in _check_solver\n",
      "    raise ValueError(\n",
      "ValueError: Solver newton-cg supports only 'l2' or 'none' penalties, got elasticnet penalty.\n",
      "\n",
      "--------------------------------------------------------------------------------\n",
      "10 fits failed with the following error:\n",
      "Traceback (most recent call last):\n",
      "  File \"c:\\Users\\ddaga\\AppData\\Local\\Programs\\Python\\Python39\\lib\\site-packages\\sklearn\\model_selection\\_validation.py\", line 686, in _fit_and_score\n",
      "    estimator.fit(X_train, y_train, **fit_params)\n",
      "  File \"c:\\Users\\ddaga\\AppData\\Local\\Programs\\Python\\Python39\\lib\\site-packages\\sklearn\\linear_model\\_logistic.py\", line 1091, in fit\n",
      "    solver = _check_solver(self.solver, self.penalty, self.dual)\n",
      "  File \"c:\\Users\\ddaga\\AppData\\Local\\Programs\\Python\\Python39\\lib\\site-packages\\sklearn\\linear_model\\_logistic.py\", line 61, in _check_solver\n",
      "    raise ValueError(\n",
      "ValueError: Solver lbfgs supports only 'l2' or 'none' penalties, got elasticnet penalty.\n",
      "\n",
      "--------------------------------------------------------------------------------\n",
      "10 fits failed with the following error:\n",
      "Traceback (most recent call last):\n",
      "  File \"c:\\Users\\ddaga\\AppData\\Local\\Programs\\Python\\Python39\\lib\\site-packages\\sklearn\\model_selection\\_validation.py\", line 686, in _fit_and_score\n",
      "    estimator.fit(X_train, y_train, **fit_params)\n",
      "  File \"c:\\Users\\ddaga\\AppData\\Local\\Programs\\Python\\Python39\\lib\\site-packages\\sklearn\\linear_model\\_logistic.py\", line 1091, in fit\n",
      "    solver = _check_solver(self.solver, self.penalty, self.dual)\n",
      "  File \"c:\\Users\\ddaga\\AppData\\Local\\Programs\\Python\\Python39\\lib\\site-packages\\sklearn\\linear_model\\_logistic.py\", line 61, in _check_solver\n",
      "    raise ValueError(\n",
      "ValueError: Solver sag supports only 'l2' or 'none' penalties, got elasticnet penalty.\n",
      "\n",
      "--------------------------------------------------------------------------------\n",
      "10 fits failed with the following error:\n",
      "Traceback (most recent call last):\n",
      "  File \"c:\\Users\\ddaga\\AppData\\Local\\Programs\\Python\\Python39\\lib\\site-packages\\sklearn\\model_selection\\_validation.py\", line 686, in _fit_and_score\n",
      "    estimator.fit(X_train, y_train, **fit_params)\n",
      "  File \"c:\\Users\\ddaga\\AppData\\Local\\Programs\\Python\\Python39\\lib\\site-packages\\sklearn\\linear_model\\_logistic.py\", line 1101, in fit\n",
      "    raise ValueError(\n",
      "ValueError: l1_ratio must be between 0 and 1; got (l1_ratio=None)\n",
      "\n",
      "--------------------------------------------------------------------------------\n",
      "50 fits failed with the following error:\n",
      "Traceback (most recent call last):\n",
      "  File \"c:\\Users\\ddaga\\AppData\\Local\\Programs\\Python\\Python39\\lib\\site-packages\\sklearn\\model_selection\\_validation.py\", line 686, in _fit_and_score\n",
      "    estimator.fit(X_train, y_train, **fit_params)\n",
      "  File \"c:\\Users\\ddaga\\AppData\\Local\\Programs\\Python\\Python39\\lib\\site-packages\\sklearn\\linear_model\\_logistic.py\", line 1091, in fit\n",
      "    solver = _check_solver(self.solver, self.penalty, self.dual)\n",
      "  File \"c:\\Users\\ddaga\\AppData\\Local\\Programs\\Python\\Python39\\lib\\site-packages\\sklearn\\linear_model\\_logistic.py\", line 55, in _check_solver\n",
      "    raise ValueError(\n",
      "ValueError: Logistic Regression supports only penalties in ['l1', 'l2', 'elasticnet', 'none'], got None.\n",
      "\n",
      "  warnings.warn(some_fits_failed_message, FitFailedWarning)\n",
      "c:\\Users\\ddaga\\AppData\\Local\\Programs\\Python\\Python39\\lib\\site-packages\\sklearn\\model_selection\\_search.py:953: UserWarning: One or more of the test scores are non-finite: [0.64122222        nan        nan        nan        nan 0.64122222\n",
      " 0.63966667 0.63933333        nan 0.63911111 0.63944444 0.63944444\n",
      "        nan        nan        nan        nan        nan        nan\n",
      "        nan        nan        nan        nan        nan        nan]\n",
      "  warnings.warn(\n",
      "c:\\Users\\ddaga\\AppData\\Local\\Programs\\Python\\Python39\\lib\\site-packages\\sklearn\\linear_model\\_sag.py:350: ConvergenceWarning: The max_iter was reached which means the coef_ did not converge\n",
      "  warnings.warn(\n",
      "c:\\Users\\ddaga\\AppData\\Local\\Programs\\Python\\Python39\\lib\\site-packages\\sklearn\\linear_model\\_sag.py:350: ConvergenceWarning: The max_iter was reached which means the coef_ did not converge\n",
      "  warnings.warn(\n",
      "c:\\Users\\ddaga\\AppData\\Local\\Programs\\Python\\Python39\\lib\\site-packages\\sklearn\\linear_model\\_sag.py:350: ConvergenceWarning: The max_iter was reached which means the coef_ did not converge\n",
      "  warnings.warn(\n",
      "c:\\Users\\ddaga\\AppData\\Local\\Programs\\Python\\Python39\\lib\\site-packages\\sklearn\\linear_model\\_sag.py:350: ConvergenceWarning: The max_iter was reached which means the coef_ did not converge\n",
      "  warnings.warn(\n",
      "c:\\Users\\ddaga\\AppData\\Local\\Programs\\Python\\Python39\\lib\\site-packages\\sklearn\\linear_model\\_sag.py:350: ConvergenceWarning: The max_iter was reached which means the coef_ did not converge\n",
      "  warnings.warn(\n",
      "c:\\Users\\ddaga\\AppData\\Local\\Programs\\Python\\Python39\\lib\\site-packages\\sklearn\\linear_model\\_sag.py:350: ConvergenceWarning: The max_iter was reached which means the coef_ did not converge\n",
      "  warnings.warn(\n",
      "c:\\Users\\ddaga\\AppData\\Local\\Programs\\Python\\Python39\\lib\\site-packages\\sklearn\\linear_model\\_sag.py:350: ConvergenceWarning: The max_iter was reached which means the coef_ did not converge\n",
      "  warnings.warn(\n",
      "c:\\Users\\ddaga\\AppData\\Local\\Programs\\Python\\Python39\\lib\\site-packages\\sklearn\\linear_model\\_sag.py:350: ConvergenceWarning: The max_iter was reached which means the coef_ did not converge\n",
      "  warnings.warn(\n",
      "c:\\Users\\ddaga\\AppData\\Local\\Programs\\Python\\Python39\\lib\\site-packages\\sklearn\\linear_model\\_sag.py:350: ConvergenceWarning: The max_iter was reached which means the coef_ did not converge\n",
      "  warnings.warn(\n",
      "c:\\Users\\ddaga\\AppData\\Local\\Programs\\Python\\Python39\\lib\\site-packages\\sklearn\\model_selection\\_validation.py:378: FitFailedWarning: \n",
      "170 fits failed out of a total of 240.\n",
      "The score on these train-test partitions for these parameters will be set to nan.\n",
      "If these failures are not expected, you can try to debug them by setting error_score='raise'.\n",
      "\n",
      "Below are more details about the failures:\n",
      "--------------------------------------------------------------------------------\n",
      "10 fits failed with the following error:\n",
      "Traceback (most recent call last):\n",
      "  File \"c:\\Users\\ddaga\\AppData\\Local\\Programs\\Python\\Python39\\lib\\site-packages\\sklearn\\model_selection\\_validation.py\", line 686, in _fit_and_score\n",
      "    estimator.fit(X_train, y_train, **fit_params)\n",
      "  File \"c:\\Users\\ddaga\\AppData\\Local\\Programs\\Python\\Python39\\lib\\site-packages\\sklearn\\linear_model\\_logistic.py\", line 1091, in fit\n",
      "    solver = _check_solver(self.solver, self.penalty, self.dual)\n",
      "  File \"c:\\Users\\ddaga\\AppData\\Local\\Programs\\Python\\Python39\\lib\\site-packages\\sklearn\\linear_model\\_logistic.py\", line 61, in _check_solver\n",
      "    raise ValueError(\n",
      "ValueError: Solver newton-cg supports only 'l2' or 'none' penalties, got l1 penalty.\n",
      "\n",
      "--------------------------------------------------------------------------------\n",
      "40 fits failed with the following error:\n",
      "Traceback (most recent call last):\n",
      "  File \"c:\\Users\\ddaga\\AppData\\Local\\Programs\\Python\\Python39\\lib\\site-packages\\sklearn\\model_selection\\_validation.py\", line 686, in _fit_and_score\n",
      "    estimator.fit(X_train, y_train, **fit_params)\n",
      "  File \"c:\\Users\\ddaga\\AppData\\Local\\Programs\\Python\\Python39\\lib\\site-packages\\sklearn\\linear_model\\_logistic.py\", line 1091, in fit\n",
      "    solver = _check_solver(self.solver, self.penalty, self.dual)\n",
      "  File \"c:\\Users\\ddaga\\AppData\\Local\\Programs\\Python\\Python39\\lib\\site-packages\\sklearn\\linear_model\\_logistic.py\", line 48, in _check_solver\n",
      "    raise ValueError(\n",
      "ValueError: Logistic Regression supports only solvers in ['liblinear', 'newton-cg', 'lbfgs', 'sag', 'saga'], got newton-cholesky.\n",
      "\n",
      "--------------------------------------------------------------------------------\n",
      "10 fits failed with the following error:\n",
      "Traceback (most recent call last):\n",
      "  File \"c:\\Users\\ddaga\\AppData\\Local\\Programs\\Python\\Python39\\lib\\site-packages\\sklearn\\model_selection\\_validation.py\", line 686, in _fit_and_score\n",
      "    estimator.fit(X_train, y_train, **fit_params)\n",
      "  File \"c:\\Users\\ddaga\\AppData\\Local\\Programs\\Python\\Python39\\lib\\site-packages\\sklearn\\linear_model\\_logistic.py\", line 1091, in fit\n",
      "    solver = _check_solver(self.solver, self.penalty, self.dual)\n",
      "  File \"c:\\Users\\ddaga\\AppData\\Local\\Programs\\Python\\Python39\\lib\\site-packages\\sklearn\\linear_model\\_logistic.py\", line 61, in _check_solver\n",
      "    raise ValueError(\n",
      "ValueError: Solver lbfgs supports only 'l2' or 'none' penalties, got l1 penalty.\n",
      "\n",
      "--------------------------------------------------------------------------------\n",
      "10 fits failed with the following error:\n",
      "Traceback (most recent call last):\n",
      "  File \"c:\\Users\\ddaga\\AppData\\Local\\Programs\\Python\\Python39\\lib\\site-packages\\sklearn\\model_selection\\_validation.py\", line 686, in _fit_and_score\n",
      "    estimator.fit(X_train, y_train, **fit_params)\n",
      "  File \"c:\\Users\\ddaga\\AppData\\Local\\Programs\\Python\\Python39\\lib\\site-packages\\sklearn\\linear_model\\_logistic.py\", line 1091, in fit\n",
      "    solver = _check_solver(self.solver, self.penalty, self.dual)\n",
      "  File \"c:\\Users\\ddaga\\AppData\\Local\\Programs\\Python\\Python39\\lib\\site-packages\\sklearn\\linear_model\\_logistic.py\", line 61, in _check_solver\n",
      "    raise ValueError(\n",
      "ValueError: Solver sag supports only 'l2' or 'none' penalties, got l1 penalty.\n",
      "\n",
      "--------------------------------------------------------------------------------\n",
      "10 fits failed with the following error:\n",
      "Traceback (most recent call last):\n",
      "  File \"c:\\Users\\ddaga\\AppData\\Local\\Programs\\Python\\Python39\\lib\\site-packages\\sklearn\\model_selection\\_validation.py\", line 686, in _fit_and_score\n",
      "    estimator.fit(X_train, y_train, **fit_params)\n",
      "  File \"c:\\Users\\ddaga\\AppData\\Local\\Programs\\Python\\Python39\\lib\\site-packages\\sklearn\\linear_model\\_logistic.py\", line 1091, in fit\n",
      "    solver = _check_solver(self.solver, self.penalty, self.dual)\n",
      "  File \"c:\\Users\\ddaga\\AppData\\Local\\Programs\\Python\\Python39\\lib\\site-packages\\sklearn\\linear_model\\_logistic.py\", line 71, in _check_solver\n",
      "    raise ValueError(\n",
      "ValueError: Only 'saga' solver supports elasticnet penalty, got solver=liblinear.\n",
      "\n",
      "--------------------------------------------------------------------------------\n",
      "10 fits failed with the following error:\n",
      "Traceback (most recent call last):\n",
      "  File \"c:\\Users\\ddaga\\AppData\\Local\\Programs\\Python\\Python39\\lib\\site-packages\\sklearn\\model_selection\\_validation.py\", line 686, in _fit_and_score\n",
      "    estimator.fit(X_train, y_train, **fit_params)\n",
      "  File \"c:\\Users\\ddaga\\AppData\\Local\\Programs\\Python\\Python39\\lib\\site-packages\\sklearn\\linear_model\\_logistic.py\", line 1091, in fit\n",
      "    solver = _check_solver(self.solver, self.penalty, self.dual)\n",
      "  File \"c:\\Users\\ddaga\\AppData\\Local\\Programs\\Python\\Python39\\lib\\site-packages\\sklearn\\linear_model\\_logistic.py\", line 61, in _check_solver\n",
      "    raise ValueError(\n",
      "ValueError: Solver newton-cg supports only 'l2' or 'none' penalties, got elasticnet penalty.\n",
      "\n",
      "--------------------------------------------------------------------------------\n",
      "10 fits failed with the following error:\n",
      "Traceback (most recent call last):\n",
      "  File \"c:\\Users\\ddaga\\AppData\\Local\\Programs\\Python\\Python39\\lib\\site-packages\\sklearn\\model_selection\\_validation.py\", line 686, in _fit_and_score\n",
      "    estimator.fit(X_train, y_train, **fit_params)\n",
      "  File \"c:\\Users\\ddaga\\AppData\\Local\\Programs\\Python\\Python39\\lib\\site-packages\\sklearn\\linear_model\\_logistic.py\", line 1091, in fit\n",
      "    solver = _check_solver(self.solver, self.penalty, self.dual)\n",
      "  File \"c:\\Users\\ddaga\\AppData\\Local\\Programs\\Python\\Python39\\lib\\site-packages\\sklearn\\linear_model\\_logistic.py\", line 61, in _check_solver\n",
      "    raise ValueError(\n",
      "ValueError: Solver lbfgs supports only 'l2' or 'none' penalties, got elasticnet penalty.\n",
      "\n",
      "--------------------------------------------------------------------------------\n",
      "10 fits failed with the following error:\n",
      "Traceback (most recent call last):\n",
      "  File \"c:\\Users\\ddaga\\AppData\\Local\\Programs\\Python\\Python39\\lib\\site-packages\\sklearn\\model_selection\\_validation.py\", line 686, in _fit_and_score\n",
      "    estimator.fit(X_train, y_train, **fit_params)\n",
      "  File \"c:\\Users\\ddaga\\AppData\\Local\\Programs\\Python\\Python39\\lib\\site-packages\\sklearn\\linear_model\\_logistic.py\", line 1091, in fit\n",
      "    solver = _check_solver(self.solver, self.penalty, self.dual)\n",
      "  File \"c:\\Users\\ddaga\\AppData\\Local\\Programs\\Python\\Python39\\lib\\site-packages\\sklearn\\linear_model\\_logistic.py\", line 61, in _check_solver\n",
      "    raise ValueError(\n",
      "ValueError: Solver sag supports only 'l2' or 'none' penalties, got elasticnet penalty.\n",
      "\n",
      "--------------------------------------------------------------------------------\n",
      "10 fits failed with the following error:\n",
      "Traceback (most recent call last):\n",
      "  File \"c:\\Users\\ddaga\\AppData\\Local\\Programs\\Python\\Python39\\lib\\site-packages\\sklearn\\model_selection\\_validation.py\", line 686, in _fit_and_score\n",
      "    estimator.fit(X_train, y_train, **fit_params)\n",
      "  File \"c:\\Users\\ddaga\\AppData\\Local\\Programs\\Python\\Python39\\lib\\site-packages\\sklearn\\linear_model\\_logistic.py\", line 1101, in fit\n",
      "    raise ValueError(\n",
      "ValueError: l1_ratio must be between 0 and 1; got (l1_ratio=None)\n",
      "\n",
      "--------------------------------------------------------------------------------\n",
      "50 fits failed with the following error:\n",
      "Traceback (most recent call last):\n",
      "  File \"c:\\Users\\ddaga\\AppData\\Local\\Programs\\Python\\Python39\\lib\\site-packages\\sklearn\\model_selection\\_validation.py\", line 686, in _fit_and_score\n",
      "    estimator.fit(X_train, y_train, **fit_params)\n",
      "  File \"c:\\Users\\ddaga\\AppData\\Local\\Programs\\Python\\Python39\\lib\\site-packages\\sklearn\\linear_model\\_logistic.py\", line 1091, in fit\n",
      "    solver = _check_solver(self.solver, self.penalty, self.dual)\n",
      "  File \"c:\\Users\\ddaga\\AppData\\Local\\Programs\\Python\\Python39\\lib\\site-packages\\sklearn\\linear_model\\_logistic.py\", line 55, in _check_solver\n",
      "    raise ValueError(\n",
      "ValueError: Logistic Regression supports only penalties in ['l1', 'l2', 'elasticnet', 'none'], got None.\n",
      "\n",
      "  warnings.warn(some_fits_failed_message, FitFailedWarning)\n",
      "c:\\Users\\ddaga\\AppData\\Local\\Programs\\Python\\Python39\\lib\\site-packages\\sklearn\\model_selection\\_search.py:953: UserWarning: One or more of the test scores are non-finite: [0.64388889        nan        nan        nan        nan 0.644\n",
      " 0.64244444 0.64288889        nan 0.64277778 0.64288889 0.64288889\n",
      "        nan        nan        nan        nan        nan        nan\n",
      "        nan        nan        nan        nan        nan        nan]\n",
      "  warnings.warn(\n"
     ]
    }
   ],
   "source": [
    "for train_index, test_index in kf.split(X):\n",
    "\n",
    "    X_train, X_test, y_train, y_test = X.iloc[train_index], X.iloc[test_index], y.iloc[train_index], y.iloc[test_index]\n",
    "\n",
    "    grid_search.fit(X_train, y_train)\n",
    "\n",
    "    best_lr = grid_search.best_estimator_\n",
    "    \n",
    "    y_scores = best_lr.decision_function(X_test)\n",
    "\n",
    "    y_pred = best_lr.predict(X_test)\n",
    "    \n",
    "    accuracy = accuracy_score(y_test, y_pred)\n",
    "    recall = recall_score(y_test, y_pred)\n",
    "    auc = roc_auc_score(y_test, y_scores)\n",
    "    \n",
    "    accuracies.append(accuracy)\n",
    "    recalls.append(recall)\n",
    "    auc_scores.append(auc)\n",
    "\n"
   ]
  },
  {
   "cell_type": "code",
   "execution_count": 14,
   "metadata": {},
   "outputs": [
    {
     "name": "stdout",
     "output_type": "stream",
     "text": [
      "Average Accuracy: 0.6432\n",
      "Average Recall: 0.7294082365358013\n",
      "Average AUC: 0.6838490603408139\n",
      "Best Hyperparameters: {'penalty': 'l1', 'solver': 'saga'}\n"
     ]
    }
   ],
   "source": [
    "print(\"Average Accuracy:\", np.mean(accuracies))\n",
    "print(\"Average Recall:\", np.mean(recalls))\n",
    "print(\"Average AUC:\", np.mean(auc_scores))\n",
    "\n",
    "print(\"Best Hyperparameters:\", grid_search.best_params_)"
   ]
  }
 ],
 "metadata": {
  "kernelspec": {
   "display_name": "Python 3",
   "language": "python",
   "name": "python3"
  },
  "language_info": {
   "codemirror_mode": {
    "name": "ipython",
    "version": 3
   },
   "file_extension": ".py",
   "mimetype": "text/x-python",
   "name": "python",
   "nbconvert_exporter": "python",
   "pygments_lexer": "ipython3",
   "version": "3.9.6"
  }
 },
 "nbformat": 4,
 "nbformat_minor": 2
}
